[2019-07-08 11:11:43,888] INFO    : /home/arcturus/Projects/sharewood/app/views.py changed, reloading.
[2019-07-08 11:22:25,175] INFO    : /home/arcturus/Projects/sharewood/app/views.py changed, reloading.
[2019-07-08 11:22:40,358] ERROR   : Internal Server Error: /api/chart/data/
Traceback (most recent call last):
  File "/home/arcturus/Projects/sharewood/venv/lib/python3.7/site-packages/django/core/handlers/exception.py", line 34, in inner
    response = get_response(request)
  File "/home/arcturus/Projects/sharewood/venv/lib/python3.7/site-packages/django/core/handlers/base.py", line 115, in _get_response
    response = self.process_exception_by_middleware(e, request)
  File "/home/arcturus/Projects/sharewood/venv/lib/python3.7/site-packages/django/core/handlers/base.py", line 113, in _get_response
    response = wrapped_callback(request, *callback_args, **callback_kwargs)
  File "/home/arcturus/Projects/sharewood/venv/lib/python3.7/site-packages/django/views/decorators/csrf.py", line 54, in wrapped_view
    return view_func(*args, **kwargs)
  File "/home/arcturus/Projects/sharewood/venv/lib/python3.7/site-packages/django/views/generic/base.py", line 71, in view
    return self.dispatch(request, *args, **kwargs)
  File "/home/arcturus/Projects/sharewood/venv/lib/python3.7/site-packages/rest_framework/views.py", line 495, in dispatch
    response = self.handle_exception(exc)
  File "/home/arcturus/Projects/sharewood/venv/lib/python3.7/site-packages/rest_framework/views.py", line 455, in handle_exception
    self.raise_uncaught_exception(exc)
  File "/home/arcturus/Projects/sharewood/venv/lib/python3.7/site-packages/rest_framework/views.py", line 492, in dispatch
    response = handler(request, *args, **kwargs)
  File "/home/arcturus/Projects/sharewood/app/views.py", line 592, in get
    "users": django.contrib.auth.User.objects.all().count(),
AttributeError: module 'django.contrib.auth' has no attribute 'User'
[2019-07-08 11:22:40,416] WARNING : Not Found: /favicon.ico
[2019-07-08 11:23:30,604] INFO    : /home/arcturus/Projects/sharewood/app/views.py changed, reloading.
[2019-07-08 11:30:45,919] INFO    : /home/arcturus/Projects/sharewood/app/urls.py changed, reloading.
[2019-07-08 11:30:55,249] INFO    : /home/arcturus/Projects/sharewood/app/urls.py changed, reloading.
[2019-07-08 11:31:16,212] INFO    : /home/arcturus/Projects/sharewood/app/urls.py changed, reloading.
[2019-07-08 11:33:25,220] INFO    : /home/arcturus/Projects/sharewood/app/urls.py changed, reloading.
[2019-07-08 11:35:03,942] INFO    : /home/arcturus/Projects/sharewood/app/urls.py changed, reloading.
[2019-07-08 11:36:29,005] INFO    : /home/arcturus/Projects/sharewood/app/views.py changed, reloading.
[2019-07-08 11:37:36,188] INFO    : /home/arcturus/Projects/sharewood/app/views.py changed, reloading.
[2019-07-08 11:38:08,021] ERROR   : Internal Server Error: /api/123
Traceback (most recent call last):
  File "/home/arcturus/Projects/sharewood/venv/lib/python3.7/site-packages/django/core/handlers/exception.py", line 34, in inner
    response = get_response(request)
  File "/home/arcturus/Projects/sharewood/venv/lib/python3.7/site-packages/django/core/handlers/base.py", line 115, in _get_response
    response = self.process_exception_by_middleware(e, request)
  File "/home/arcturus/Projects/sharewood/venv/lib/python3.7/site-packages/django/core/handlers/base.py", line 113, in _get_response
    response = wrapped_callback(request, *callback_args, **callback_kwargs)
  File "/home/arcturus/Projects/sharewood/app/views.py", line 514, in api
    return getattr(views_app, data)()
NameError: name 'views_app' is not defined
[2019-07-08 11:38:30,145] INFO    : /home/arcturus/Projects/sharewood/app/views.py changed, reloading.
[2019-07-08 11:38:33,044] INFO    : /home/arcturus/Projects/sharewood/app/views.py changed, reloading.
[2019-07-08 11:38:35,321] ERROR   : Internal Server Error: /api/123
Traceback (most recent call last):
  File "/home/arcturus/Projects/sharewood/venv/lib/python3.7/site-packages/django/core/handlers/exception.py", line 34, in inner
    response = get_response(request)
  File "/home/arcturus/Projects/sharewood/venv/lib/python3.7/site-packages/django/core/handlers/base.py", line 115, in _get_response
    response = self.process_exception_by_middleware(e, request)
  File "/home/arcturus/Projects/sharewood/venv/lib/python3.7/site-packages/django/core/handlers/base.py", line 113, in _get_response
    response = wrapped_callback(request, *callback_args, **callback_kwargs)
  File "/home/arcturus/Projects/sharewood/app/views.py", line 514, in api
    return getattr(app.views_app, data)()
AttributeError: module 'app' has no attribute 'views_app'
[2019-07-08 11:39:14,112] INFO    : /home/arcturus/Projects/sharewood/app/views.py changed, reloading.
[2019-07-08 11:39:27,560] INFO    : /home/arcturus/Projects/sharewood/app/views.py changed, reloading.
[2019-07-08 11:39:28,927] ERROR   : Internal Server Error: /api/123
Traceback (most recent call last):
  File "/home/arcturus/Projects/sharewood/venv/lib/python3.7/site-packages/django/core/handlers/exception.py", line 34, in inner
    response = get_response(request)
  File "/home/arcturus/Projects/sharewood/venv/lib/python3.7/site-packages/django/core/handlers/base.py", line 115, in _get_response
    response = self.process_exception_by_middleware(e, request)
  File "/home/arcturus/Projects/sharewood/venv/lib/python3.7/site-packages/django/core/handlers/base.py", line 113, in _get_response
    response = wrapped_callback(request, *callback_args, **callback_kwargs)
  File "/home/arcturus/Projects/sharewood/app/views.py", line 514, in api
    return getattr(views_api, data)()
NameError: name 'views_api' is not defined
[2019-07-08 11:39:46,317] INFO    : /home/arcturus/Projects/sharewood/app/views.py changed, reloading.
[2019-07-08 11:39:47,902] ERROR   : Internal Server Error: /api/123
Traceback (most recent call last):
  File "/home/arcturus/Projects/sharewood/venv/lib/python3.7/site-packages/django/core/handlers/exception.py", line 34, in inner
    response = get_response(request)
  File "/home/arcturus/Projects/sharewood/venv/lib/python3.7/site-packages/django/core/handlers/base.py", line 115, in _get_response
    response = self.process_exception_by_middleware(e, request)
  File "/home/arcturus/Projects/sharewood/venv/lib/python3.7/site-packages/django/core/handlers/base.py", line 113, in _get_response
    response = wrapped_callback(request, *callback_args, **callback_kwargs)
  File "/home/arcturus/Projects/sharewood/app/views.py", line 514, in api
    return getattr(app.views_api, data)()
AttributeError: module 'app.views_api' has no attribute '123'
[2019-07-08 11:39:47,961] WARNING : Not Found: /favicon.ico
[2019-07-08 11:40:56,680] INFO    : /home/arcturus/Projects/sharewood/app/views_api.py changed, reloading.
[2019-07-08 11:41:24,566] ERROR   : Internal Server Error: /api/123
Traceback (most recent call last):
  File "/home/arcturus/Projects/sharewood/venv/lib/python3.7/site-packages/django/core/handlers/exception.py", line 34, in inner
    response = get_response(request)
  File "/home/arcturus/Projects/sharewood/venv/lib/python3.7/site-packages/django/core/handlers/base.py", line 115, in _get_response
    response = self.process_exception_by_middleware(e, request)
  File "/home/arcturus/Projects/sharewood/venv/lib/python3.7/site-packages/django/core/handlers/base.py", line 113, in _get_response
    response = wrapped_callback(request, *callback_args, **callback_kwargs)
  File "/home/arcturus/Projects/sharewood/app/views.py", line 514, in api
    return getattr(app.views_api, data)(request)
AttributeError: module 'app.views_api' has no attribute '123'
[2019-07-08 11:41:24,590] WARNING : Not Found: /favicon.ico
[2019-07-08 11:42:01,076] INFO    : /home/arcturus/Projects/sharewood/app/views.py changed, reloading.
[2019-07-08 11:42:41,069] WARNING : Not Found: /api/regi
[2019-07-08 11:42:42,172] WARNING : Not Found: /api/regi
[2019-07-08 11:42:42,192] WARNING : Not Found: /favicon.ico
[2019-07-08 11:42:48,774] WARNING : Not Found: /api/regi
[2019-07-08 11:42:49,139] INFO    : /home/arcturus/Projects/sharewood/app/views.py changed, reloading.
[2019-07-08 11:42:50,119] WARNING : Not Found: /api/regi
[2019-07-08 11:42:50,136] WARNING : Not Found: /favicon.ico
[2019-07-08 11:42:50,368] WARNING : Not Found: /api/regi
[2019-07-08 11:42:50,431] WARNING : Not Found: /api/regi
[2019-07-08 11:42:50,466] WARNING : Not Found: /api/regi
[2019-07-08 11:42:50,531] WARNING : Not Found: /api/regi
[2019-07-08 11:42:50,854] WARNING : Not Found: /api/regi
[2019-07-08 11:50:01,393] INFO    : /home/arcturus/Projects/sharewood/app/views.py changed, reloading.
[2019-07-08 11:50:03,772] WARNING : Not Found: /api/regi
[2019-07-08 11:50:03,801] WARNING : Not Found: /favicon.ico
[2019-07-08 11:50:13,470] WARNING : Not Found: /api/regi
[2019-07-08 11:51:18,536] ERROR   : Internal Server Error: /api/registration
Traceback (most recent call last):
  File "/home/arcturus/Projects/sharewood/venv/lib/python3.7/site-packages/django/core/handlers/exception.py", line 34, in inner
    response = get_response(request)
  File "/home/arcturus/Projects/sharewood/venv/lib/python3.7/site-packages/django/core/handlers/base.py", line 126, in _get_response
    "returned None instead." % (callback.__module__, view_name)
ValueError: The view app.views.api didn't return an HttpResponse object. It returned None instead.
[2019-07-08 11:52:42,894] INFO    : /home/arcturus/Projects/sharewood/app/views.py changed, reloading.
[2019-07-08 11:55:09,152] INFO    : /home/arcturus/Projects/sharewood/app/views_api.py changed, reloading.
[2019-07-08 11:56:33,529] INFO    : /home/arcturus/Projects/sharewood/app/urls.py changed, reloading.
[2019-07-08 11:56:36,212] ERROR   : Internal Server Error: /api/registration
Traceback (most recent call last):
  File "/home/arcturus/Projects/sharewood/venv/lib/python3.7/site-packages/django/core/handlers/exception.py", line 34, in inner
    response = get_response(request)
  File "/home/arcturus/Projects/sharewood/venv/lib/python3.7/site-packages/django/core/handlers/base.py", line 115, in _get_response
    response = self.process_exception_by_middleware(e, request)
  File "/home/arcturus/Projects/sharewood/venv/lib/python3.7/site-packages/django/core/handlers/base.py", line 113, in _get_response
    response = wrapped_callback(request, *callback_args, **callback_kwargs)
  File "/home/arcturus/Projects/sharewood/app/views.py", line 515, in api
    return getattr(app.views_api, data)(request)
  File "/home/arcturus/Projects/sharewood/app/views_api.py", line 9, in registration
    return django.http.JsonResponse(data)
  File "/home/arcturus/Projects/sharewood/venv/lib/python3.7/site-packages/django/http/response.py", line 552, in __init__
    'In order to allow non-dict objects to be serialized set the '
TypeError: In order to allow non-dict objects to be serialized set the safe parameter to False.
[2019-07-08 11:56:56,551] INFO    : /home/arcturus/Projects/sharewood/app/views_api.py changed, reloading.
[2019-07-08 11:56:57,334] WARNING : Not Found: /api/registration
[2019-07-08 11:57:06,829] WARNING : Not Found: /api/registration
[2019-07-08 11:57:07,635] WARNING : Not Found: /api/registration
[2019-07-08 11:57:50,975] WARNING : Not Found: /api/registratio
[2019-07-08 11:57:53,223] WARNING : Not Found: /api/registration
[2019-07-08 11:57:59,371] WARNING : Not Found: /api/registration
[2019-07-08 11:57:59,787] WARNING : Not Found: /api/registration
[2019-07-08 11:57:59,997] WARNING : Not Found: /api/registration
[2019-07-08 11:58:00,158] WARNING : Not Found: /api/registration
[2019-07-08 11:58:00,305] WARNING : Not Found: /api/registration
[2019-07-08 11:58:00,458] WARNING : Not Found: /api/registration
[2019-07-08 11:58:06,771] WARNING : Not Found: /api/registration
[2019-07-08 11:58:07,166] WARNING : Not Found: /api/registration
[2019-07-08 11:58:07,374] WARNING : Not Found: /api/registration
[2019-07-08 11:58:07,544] WARNING : Not Found: /api/registration
[2019-07-08 11:58:57,100] WARNING : Not Found: /api/
[2019-07-08 11:59:07,786] WARNING : Not Found: /api/registration
[2019-07-08 11:59:47,297] WARNING : Not Found: /api/registration
[2019-07-08 11:59:47,317] INFO    : /home/arcturus/Projects/sharewood/app/views.py changed, reloading.
[2019-07-08 11:59:48,710] WARNING : Not Found: /api/registration
[2019-07-08 11:59:49,148] WARNING : Not Found: /api/registration
[2019-07-08 12:00:05,211] INFO    : /home/arcturus/Projects/sharewood/app/views_api.py changed, reloading.
[2019-07-08 12:00:06,164] ERROR   : Internal Server Error: /api/registration
Traceback (most recent call last):
  File "/home/arcturus/Projects/sharewood/venv/lib/python3.7/site-packages/django/core/handlers/exception.py", line 34, in inner
    response = get_response(request)
  File "/home/arcturus/Projects/sharewood/venv/lib/python3.7/site-packages/django/core/handlers/base.py", line 115, in _get_response
    response = self.process_exception_by_middleware(e, request)
  File "/home/arcturus/Projects/sharewood/venv/lib/python3.7/site-packages/django/core/handlers/base.py", line 113, in _get_response
    response = wrapped_callback(request, *callback_args, **callback_kwargs)
  File "/home/arcturus/Projects/sharewood/app/views.py", line 515, in api
    return getattr(app.views_api, data)(request)
  File "/home/arcturus/Projects/sharewood/app/views_api.py", line 9, in registration
    return django.http.JsonResponse(data)
  File "/home/arcturus/Projects/sharewood/venv/lib/python3.7/site-packages/django/http/response.py", line 552, in __init__
    'In order to allow non-dict objects to be serialized set the '
TypeError: In order to allow non-dict objects to be serialized set the safe parameter to False.
[2019-07-08 12:00:06,792] ERROR   : Internal Server Error: /api/registration
Traceback (most recent call last):
  File "/home/arcturus/Projects/sharewood/venv/lib/python3.7/site-packages/django/core/handlers/exception.py", line 34, in inner
    response = get_response(request)
  File "/home/arcturus/Projects/sharewood/venv/lib/python3.7/site-packages/django/core/handlers/base.py", line 115, in _get_response
    response = self.process_exception_by_middleware(e, request)
  File "/home/arcturus/Projects/sharewood/venv/lib/python3.7/site-packages/django/core/handlers/base.py", line 113, in _get_response
    response = wrapped_callback(request, *callback_args, **callback_kwargs)
  File "/home/arcturus/Projects/sharewood/app/views.py", line 515, in api
    return getattr(app.views_api, data)(request)
  File "/home/arcturus/Projects/sharewood/app/views_api.py", line 9, in registration
    return django.http.JsonResponse(data)
  File "/home/arcturus/Projects/sharewood/venv/lib/python3.7/site-packages/django/http/response.py", line 552, in __init__
    'In order to allow non-dict objects to be serialized set the '
TypeError: In order to allow non-dict objects to be serialized set the safe parameter to False.
[2019-07-08 12:00:27,120] INFO    : /home/arcturus/Projects/sharewood/app/views_api.py changed, reloading.
[2019-07-08 12:00:27,965] WARNING : Not Found: /api/registration
[2019-07-08 12:00:28,187] WARNING : Not Found: /api/registration
[2019-07-08 12:00:34,199] WARNING : Not Found: /api/registration
[2019-07-08 12:00:34,253] INFO    : /home/arcturus/Projects/sharewood/app/views_api.py changed, reloading.
[2019-07-08 12:00:35,080] ERROR   : Internal Server Error: /api/registration
Traceback (most recent call last):
  File "/home/arcturus/Projects/sharewood/venv/lib/python3.7/site-packages/django/core/handlers/exception.py", line 34, in inner
    response = get_response(request)
  File "/home/arcturus/Projects/sharewood/venv/lib/python3.7/site-packages/django/core/handlers/base.py", line 115, in _get_response
    response = self.process_exception_by_middleware(e, request)
  File "/home/arcturus/Projects/sharewood/venv/lib/python3.7/site-packages/django/core/handlers/base.py", line 113, in _get_response
    response = wrapped_callback(request, *callback_args, **callback_kwargs)
  File "/home/arcturus/Projects/sharewood/app/views.py", line 515, in api
    return getattr(app.views_api, data)(request)
  File "/home/arcturus/Projects/sharewood/app/views_api.py", line 9, in registration
    return django.http.JsonResponse(data)
  File "/home/arcturus/Projects/sharewood/venv/lib/python3.7/site-packages/django/http/response.py", line 552, in __init__
    'In order to allow non-dict objects to be serialized set the '
TypeError: In order to allow non-dict objects to be serialized set the safe parameter to False.
[2019-07-08 12:00:35,131] ERROR   : Internal Server Error: /api/registration
Traceback (most recent call last):
  File "/home/arcturus/Projects/sharewood/venv/lib/python3.7/site-packages/django/core/handlers/exception.py", line 34, in inner
    response = get_response(request)
  File "/home/arcturus/Projects/sharewood/venv/lib/python3.7/site-packages/django/core/handlers/base.py", line 115, in _get_response
    response = self.process_exception_by_middleware(e, request)
  File "/home/arcturus/Projects/sharewood/venv/lib/python3.7/site-packages/django/core/handlers/base.py", line 113, in _get_response
    response = wrapped_callback(request, *callback_args, **callback_kwargs)
  File "/home/arcturus/Projects/sharewood/app/views.py", line 515, in api
    return getattr(app.views_api, data)(request)
  File "/home/arcturus/Projects/sharewood/app/views_api.py", line 9, in registration
    return django.http.JsonResponse(data)
  File "/home/arcturus/Projects/sharewood/venv/lib/python3.7/site-packages/django/http/response.py", line 552, in __init__
    'In order to allow non-dict objects to be serialized set the '
TypeError: In order to allow non-dict objects to be serialized set the safe parameter to False.
[2019-07-08 12:00:35,173] ERROR   : Internal Server Error: /api/registration
Traceback (most recent call last):
  File "/home/arcturus/Projects/sharewood/venv/lib/python3.7/site-packages/django/core/handlers/exception.py", line 34, in inner
    response = get_response(request)
  File "/home/arcturus/Projects/sharewood/venv/lib/python3.7/site-packages/django/core/handlers/base.py", line 115, in _get_response
    response = self.process_exception_by_middleware(e, request)
  File "/home/arcturus/Projects/sharewood/venv/lib/python3.7/site-packages/django/core/handlers/base.py", line 113, in _get_response
    response = wrapped_callback(request, *callback_args, **callback_kwargs)
  File "/home/arcturus/Projects/sharewood/app/views.py", line 515, in api
    return getattr(app.views_api, data)(request)
  File "/home/arcturus/Projects/sharewood/app/views_api.py", line 9, in registration
    return django.http.JsonResponse(data)
  File "/home/arcturus/Projects/sharewood/venv/lib/python3.7/site-packages/django/http/response.py", line 552, in __init__
    'In order to allow non-dict objects to be serialized set the '
TypeError: In order to allow non-dict objects to be serialized set the safe parameter to False.
[2019-07-08 12:00:35,237] ERROR   : Internal Server Error: /api/registration
Traceback (most recent call last):
  File "/home/arcturus/Projects/sharewood/venv/lib/python3.7/site-packages/django/core/handlers/exception.py", line 34, in inner
    response = get_response(request)
  File "/home/arcturus/Projects/sharewood/venv/lib/python3.7/site-packages/django/core/handlers/base.py", line 115, in _get_response
    response = self.process_exception_by_middleware(e, request)
  File "/home/arcturus/Projects/sharewood/venv/lib/python3.7/site-packages/django/core/handlers/base.py", line 113, in _get_response
    response = wrapped_callback(request, *callback_args, **callback_kwargs)
  File "/home/arcturus/Projects/sharewood/app/views.py", line 515, in api
    return getattr(app.views_api, data)(request)
  File "/home/arcturus/Projects/sharewood/app/views_api.py", line 9, in registration
    return django.http.JsonResponse(data)
  File "/home/arcturus/Projects/sharewood/venv/lib/python3.7/site-packages/django/http/response.py", line 552, in __init__
    'In order to allow non-dict objects to be serialized set the '
TypeError: In order to allow non-dict objects to be serialized set the safe parameter to False.
[2019-07-08 12:00:35,276] ERROR   : Internal Server Error: /api/registration
Traceback (most recent call last):
  File "/home/arcturus/Projects/sharewood/venv/lib/python3.7/site-packages/django/core/handlers/exception.py", line 34, in inner
    response = get_response(request)
  File "/home/arcturus/Projects/sharewood/venv/lib/python3.7/site-packages/django/core/handlers/base.py", line 115, in _get_response
    response = self.process_exception_by_middleware(e, request)
  File "/home/arcturus/Projects/sharewood/venv/lib/python3.7/site-packages/django/core/handlers/base.py", line 113, in _get_response
    response = wrapped_callback(request, *callback_args, **callback_kwargs)
  File "/home/arcturus/Projects/sharewood/app/views.py", line 515, in api
    return getattr(app.views_api, data)(request)
  File "/home/arcturus/Projects/sharewood/app/views_api.py", line 9, in registration
    return django.http.JsonResponse(data)
  File "/home/arcturus/Projects/sharewood/venv/lib/python3.7/site-packages/django/http/response.py", line 552, in __init__
    'In order to allow non-dict objects to be serialized set the '
TypeError: In order to allow non-dict objects to be serialized set the safe parameter to False.
[2019-07-08 12:00:35,318] ERROR   : Internal Server Error: /api/registration
Traceback (most recent call last):
  File "/home/arcturus/Projects/sharewood/venv/lib/python3.7/site-packages/django/core/handlers/exception.py", line 34, in inner
    response = get_response(request)
  File "/home/arcturus/Projects/sharewood/venv/lib/python3.7/site-packages/django/core/handlers/base.py", line 115, in _get_response
    response = self.process_exception_by_middleware(e, request)
  File "/home/arcturus/Projects/sharewood/venv/lib/python3.7/site-packages/django/core/handlers/base.py", line 113, in _get_response
    response = wrapped_callback(request, *callback_args, **callback_kwargs)
  File "/home/arcturus/Projects/sharewood/app/views.py", line 515, in api
    return getattr(app.views_api, data)(request)
  File "/home/arcturus/Projects/sharewood/app/views_api.py", line 9, in registration
    return django.http.JsonResponse(data)
  File "/home/arcturus/Projects/sharewood/venv/lib/python3.7/site-packages/django/http/response.py", line 552, in __init__
    'In order to allow non-dict objects to be serialized set the '
TypeError: In order to allow non-dict objects to be serialized set the safe parameter to False.
[2019-07-08 12:00:35,417] ERROR   : Internal Server Error: /api/registration
Traceback (most recent call last):
  File "/home/arcturus/Projects/sharewood/venv/lib/python3.7/site-packages/django/core/handlers/exception.py", line 34, in inner
    response = get_response(request)
  File "/home/arcturus/Projects/sharewood/venv/lib/python3.7/site-packages/django/core/handlers/base.py", line 115, in _get_response
    response = self.process_exception_by_middleware(e, request)
  File "/home/arcturus/Projects/sharewood/venv/lib/python3.7/site-packages/django/core/handlers/base.py", line 113, in _get_response
    response = wrapped_callback(request, *callback_args, **callback_kwargs)
  File "/home/arcturus/Projects/sharewood/app/views.py", line 515, in api
    return getattr(app.views_api, data)(request)
  File "/home/arcturus/Projects/sharewood/app/views_api.py", line 9, in registration
    return django.http.JsonResponse(data)
  File "/home/arcturus/Projects/sharewood/venv/lib/python3.7/site-packages/django/http/response.py", line 552, in __init__
    'In order to allow non-dict objects to be serialized set the '
TypeError: In order to allow non-dict objects to be serialized set the safe parameter to False.
[2019-07-08 12:00:35,468] ERROR   : Internal Server Error: /api/registration
Traceback (most recent call last):
  File "/home/arcturus/Projects/sharewood/venv/lib/python3.7/site-packages/django/core/handlers/exception.py", line 34, in inner
    response = get_response(request)
  File "/home/arcturus/Projects/sharewood/venv/lib/python3.7/site-packages/django/core/handlers/base.py", line 115, in _get_response
    response = self.process_exception_by_middleware(e, request)
  File "/home/arcturus/Projects/sharewood/venv/lib/python3.7/site-packages/django/core/handlers/base.py", line 113, in _get_response
    response = wrapped_callback(request, *callback_args, **callback_kwargs)
  File "/home/arcturus/Projects/sharewood/app/views.py", line 515, in api
    return getattr(app.views_api, data)(request)
  File "/home/arcturus/Projects/sharewood/app/views_api.py", line 9, in registration
    return django.http.JsonResponse(data)
  File "/home/arcturus/Projects/sharewood/venv/lib/python3.7/site-packages/django/http/response.py", line 552, in __init__
    'In order to allow non-dict objects to be serialized set the '
TypeError: In order to allow non-dict objects to be serialized set the safe parameter to False.
[2019-07-08 12:00:35,496] ERROR   : Internal Server Error: /api/registration
Traceback (most recent call last):
  File "/home/arcturus/Projects/sharewood/venv/lib/python3.7/site-packages/django/core/handlers/exception.py", line 34, in inner
    response = get_response(request)
  File "/home/arcturus/Projects/sharewood/venv/lib/python3.7/site-packages/django/core/handlers/base.py", line 115, in _get_response
    response = self.process_exception_by_middleware(e, request)
  File "/home/arcturus/Projects/sharewood/venv/lib/python3.7/site-packages/django/core/handlers/base.py", line 113, in _get_response
    response = wrapped_callback(request, *callback_args, **callback_kwargs)
  File "/home/arcturus/Projects/sharewood/app/views.py", line 515, in api
    return getattr(app.views_api, data)(request)
  File "/home/arcturus/Projects/sharewood/app/views_api.py", line 9, in registration
    return django.http.JsonResponse(data)
  File "/home/arcturus/Projects/sharewood/venv/lib/python3.7/site-packages/django/http/response.py", line 552, in __init__
    'In order to allow non-dict objects to be serialized set the '
TypeError: In order to allow non-dict objects to be serialized set the safe parameter to False.
[2019-07-08 12:00:35,534] ERROR   : Internal Server Error: /api/registration
Traceback (most recent call last):
  File "/home/arcturus/Projects/sharewood/venv/lib/python3.7/site-packages/django/core/handlers/exception.py", line 34, in inner
    response = get_response(request)
  File "/home/arcturus/Projects/sharewood/venv/lib/python3.7/site-packages/django/core/handlers/base.py", line 115, in _get_response
    response = self.process_exception_by_middleware(e, request)
  File "/home/arcturus/Projects/sharewood/venv/lib/python3.7/site-packages/django/core/handlers/base.py", line 113, in _get_response
    response = wrapped_callback(request, *callback_args, **callback_kwargs)
  File "/home/arcturus/Projects/sharewood/app/views.py", line 515, in api
    return getattr(app.views_api, data)(request)
  File "/home/arcturus/Projects/sharewood/app/views_api.py", line 9, in registration
    return django.http.JsonResponse(data)
  File "/home/arcturus/Projects/sharewood/venv/lib/python3.7/site-packages/django/http/response.py", line 552, in __init__
    'In order to allow non-dict objects to be serialized set the '
TypeError: In order to allow non-dict objects to be serialized set the safe parameter to False.
[2019-07-08 12:00:35,567] ERROR   : Internal Server Error: /api/registration
Traceback (most recent call last):
  File "/home/arcturus/Projects/sharewood/venv/lib/python3.7/site-packages/django/core/handlers/exception.py", line 34, in inner
    response = get_response(request)
  File "/home/arcturus/Projects/sharewood/venv/lib/python3.7/site-packages/django/core/handlers/base.py", line 115, in _get_response
    response = self.process_exception_by_middleware(e, request)
  File "/home/arcturus/Projects/sharewood/venv/lib/python3.7/site-packages/django/core/handlers/base.py", line 113, in _get_response
    response = wrapped_callback(request, *callback_args, **callback_kwargs)
  File "/home/arcturus/Projects/sharewood/app/views.py", line 515, in api
    return getattr(app.views_api, data)(request)
  File "/home/arcturus/Projects/sharewood/app/views_api.py", line 9, in registration
    return django.http.JsonResponse(data)
  File "/home/arcturus/Projects/sharewood/venv/lib/python3.7/site-packages/django/http/response.py", line 552, in __init__
    'In order to allow non-dict objects to be serialized set the '
TypeError: In order to allow non-dict objects to be serialized set the safe parameter to False.
[2019-07-08 12:00:35,654] ERROR   : Internal Server Error: /api/registration
Traceback (most recent call last):
  File "/home/arcturus/Projects/sharewood/venv/lib/python3.7/site-packages/django/core/handlers/exception.py", line 34, in inner
    response = get_response(request)
  File "/home/arcturus/Projects/sharewood/venv/lib/python3.7/site-packages/django/core/handlers/base.py", line 115, in _get_response
    response = self.process_exception_by_middleware(e, request)
  File "/home/arcturus/Projects/sharewood/venv/lib/python3.7/site-packages/django/core/handlers/base.py", line 113, in _get_response
    response = wrapped_callback(request, *callback_args, **callback_kwargs)
  File "/home/arcturus/Projects/sharewood/app/views.py", line 515, in api
    return getattr(app.views_api, data)(request)
  File "/home/arcturus/Projects/sharewood/app/views_api.py", line 9, in registration
    return django.http.JsonResponse(data)
  File "/home/arcturus/Projects/sharewood/venv/lib/python3.7/site-packages/django/http/response.py", line 552, in __init__
    'In order to allow non-dict objects to be serialized set the '
TypeError: In order to allow non-dict objects to be serialized set the safe parameter to False.
[2019-07-08 12:00:35,688] ERROR   : Internal Server Error: /api/registration
Traceback (most recent call last):
  File "/home/arcturus/Projects/sharewood/venv/lib/python3.7/site-packages/django/core/handlers/exception.py", line 34, in inner
    response = get_response(request)
  File "/home/arcturus/Projects/sharewood/venv/lib/python3.7/site-packages/django/core/handlers/base.py", line 115, in _get_response
    response = self.process_exception_by_middleware(e, request)
  File "/home/arcturus/Projects/sharewood/venv/lib/python3.7/site-packages/django/core/handlers/base.py", line 113, in _get_response
    response = wrapped_callback(request, *callback_args, **callback_kwargs)
  File "/home/arcturus/Projects/sharewood/app/views.py", line 515, in api
    return getattr(app.views_api, data)(request)
  File "/home/arcturus/Projects/sharewood/app/views_api.py", line 9, in registration
    return django.http.JsonResponse(data)
  File "/home/arcturus/Projects/sharewood/venv/lib/python3.7/site-packages/django/http/response.py", line 552, in __init__
    'In order to allow non-dict objects to be serialized set the '
TypeError: In order to allow non-dict objects to be serialized set the safe parameter to False.
[2019-07-08 12:00:35,723] ERROR   : Internal Server Error: /api/registration
Traceback (most recent call last):
  File "/home/arcturus/Projects/sharewood/venv/lib/python3.7/site-packages/django/core/handlers/exception.py", line 34, in inner
    response = get_response(request)
  File "/home/arcturus/Projects/sharewood/venv/lib/python3.7/site-packages/django/core/handlers/base.py", line 115, in _get_response
    response = self.process_exception_by_middleware(e, request)
  File "/home/arcturus/Projects/sharewood/venv/lib/python3.7/site-packages/django/core/handlers/base.py", line 113, in _get_response
    response = wrapped_callback(request, *callback_args, **callback_kwargs)
  File "/home/arcturus/Projects/sharewood/app/views.py", line 515, in api
    return getattr(app.views_api, data)(request)
  File "/home/arcturus/Projects/sharewood/app/views_api.py", line 9, in registration
    return django.http.JsonResponse(data)
  File "/home/arcturus/Projects/sharewood/venv/lib/python3.7/site-packages/django/http/response.py", line 552, in __init__
    'In order to allow non-dict objects to be serialized set the '
TypeError: In order to allow non-dict objects to be serialized set the safe parameter to False.
[2019-07-08 12:00:35,767] ERROR   : Internal Server Error: /api/registration
Traceback (most recent call last):
  File "/home/arcturus/Projects/sharewood/venv/lib/python3.7/site-packages/django/core/handlers/exception.py", line 34, in inner
    response = get_response(request)
  File "/home/arcturus/Projects/sharewood/venv/lib/python3.7/site-packages/django/core/handlers/base.py", line 115, in _get_response
    response = self.process_exception_by_middleware(e, request)
  File "/home/arcturus/Projects/sharewood/venv/lib/python3.7/site-packages/django/core/handlers/base.py", line 113, in _get_response
    response = wrapped_callback(request, *callback_args, **callback_kwargs)
  File "/home/arcturus/Projects/sharewood/app/views.py", line 515, in api
    return getattr(app.views_api, data)(request)
  File "/home/arcturus/Projects/sharewood/app/views_api.py", line 9, in registration
    return django.http.JsonResponse(data)
  File "/home/arcturus/Projects/sharewood/venv/lib/python3.7/site-packages/django/http/response.py", line 552, in __init__
    'In order to allow non-dict objects to be serialized set the '
TypeError: In order to allow non-dict objects to be serialized set the safe parameter to False.
[2019-07-08 12:00:35,854] ERROR   : Internal Server Error: /api/registration
Traceback (most recent call last):
  File "/home/arcturus/Projects/sharewood/venv/lib/python3.7/site-packages/django/core/handlers/exception.py", line 34, in inner
    response = get_response(request)
  File "/home/arcturus/Projects/sharewood/venv/lib/python3.7/site-packages/django/core/handlers/base.py", line 115, in _get_response
    response = self.process_exception_by_middleware(e, request)
  File "/home/arcturus/Projects/sharewood/venv/lib/python3.7/site-packages/django/core/handlers/base.py", line 113, in _get_response
    response = wrapped_callback(request, *callback_args, **callback_kwargs)
  File "/home/arcturus/Projects/sharewood/app/views.py", line 515, in api
    return getattr(app.views_api, data)(request)
  File "/home/arcturus/Projects/sharewood/app/views_api.py", line 9, in registration
    return django.http.JsonResponse(data)
  File "/home/arcturus/Projects/sharewood/venv/lib/python3.7/site-packages/django/http/response.py", line 552, in __init__
    'In order to allow non-dict objects to be serialized set the '
TypeError: In order to allow non-dict objects to be serialized set the safe parameter to False.
[2019-07-08 12:00:35,892] ERROR   : Internal Server Error: /api/registration
Traceback (most recent call last):
  File "/home/arcturus/Projects/sharewood/venv/lib/python3.7/site-packages/django/core/handlers/exception.py", line 34, in inner
    response = get_response(request)
  File "/home/arcturus/Projects/sharewood/venv/lib/python3.7/site-packages/django/core/handlers/base.py", line 115, in _get_response
    response = self.process_exception_by_middleware(e, request)
  File "/home/arcturus/Projects/sharewood/venv/lib/python3.7/site-packages/django/core/handlers/base.py", line 113, in _get_response
    response = wrapped_callback(request, *callback_args, **callback_kwargs)
  File "/home/arcturus/Projects/sharewood/app/views.py", line 515, in api
    return getattr(app.views_api, data)(request)
  File "/home/arcturus/Projects/sharewood/app/views_api.py", line 9, in registration
    return django.http.JsonResponse(data)
  File "/home/arcturus/Projects/sharewood/venv/lib/python3.7/site-packages/django/http/response.py", line 552, in __init__
    'In order to allow non-dict objects to be serialized set the '
TypeError: In order to allow non-dict objects to be serialized set the safe parameter to False.
[2019-07-08 12:00:36,462] ERROR   : Internal Server Error: /api/registration
Traceback (most recent call last):
  File "/home/arcturus/Projects/sharewood/venv/lib/python3.7/site-packages/django/core/handlers/exception.py", line 34, in inner
    response = get_response(request)
  File "/home/arcturus/Projects/sharewood/venv/lib/python3.7/site-packages/django/core/handlers/base.py", line 115, in _get_response
    response = self.process_exception_by_middleware(e, request)
  File "/home/arcturus/Projects/sharewood/venv/lib/python3.7/site-packages/django/core/handlers/base.py", line 113, in _get_response
    response = wrapped_callback(request, *callback_args, **callback_kwargs)
  File "/home/arcturus/Projects/sharewood/app/views.py", line 515, in api
    return getattr(app.views_api, data)(request)
  File "/home/arcturus/Projects/sharewood/app/views_api.py", line 9, in registration
    return django.http.JsonResponse(data)
  File "/home/arcturus/Projects/sharewood/venv/lib/python3.7/site-packages/django/http/response.py", line 552, in __init__
    'In order to allow non-dict objects to be serialized set the '
TypeError: In order to allow non-dict objects to be serialized set the safe parameter to False.
[2019-07-08 12:00:36,796] ERROR   : Internal Server Error: /api/registration
Traceback (most recent call last):
  File "/home/arcturus/Projects/sharewood/venv/lib/python3.7/site-packages/django/core/handlers/exception.py", line 34, in inner
    response = get_response(request)
  File "/home/arcturus/Projects/sharewood/venv/lib/python3.7/site-packages/django/core/handlers/base.py", line 115, in _get_response
    response = self.process_exception_by_middleware(e, request)
  File "/home/arcturus/Projects/sharewood/venv/lib/python3.7/site-packages/django/core/handlers/base.py", line 113, in _get_response
    response = wrapped_callback(request, *callback_args, **callback_kwargs)
  File "/home/arcturus/Projects/sharewood/app/views.py", line 515, in api
    return getattr(app.views_api, data)(request)
  File "/home/arcturus/Projects/sharewood/app/views_api.py", line 9, in registration
    return django.http.JsonResponse(data)
  File "/home/arcturus/Projects/sharewood/venv/lib/python3.7/site-packages/django/http/response.py", line 552, in __init__
    'In order to allow non-dict objects to be serialized set the '
TypeError: In order to allow non-dict objects to be serialized set the safe parameter to False.
[2019-07-08 12:01:24,585] ERROR   : Internal Server Error: /api/registration
Traceback (most recent call last):
  File "/home/arcturus/Projects/sharewood/venv/lib/python3.7/site-packages/django/core/handlers/exception.py", line 34, in inner
    response = get_response(request)
  File "/home/arcturus/Projects/sharewood/venv/lib/python3.7/site-packages/django/core/handlers/base.py", line 115, in _get_response
    response = self.process_exception_by_middleware(e, request)
  File "/home/arcturus/Projects/sharewood/venv/lib/python3.7/site-packages/django/core/handlers/base.py", line 113, in _get_response
    response = wrapped_callback(request, *callback_args, **callback_kwargs)
  File "/home/arcturus/Projects/sharewood/app/views.py", line 515, in api
    return getattr(app.views_api, data)(request)
  File "/home/arcturus/Projects/sharewood/app/views_api.py", line 9, in registration
    return django.http.JsonResponse({1: 100})
  File "/home/arcturus/Projects/sharewood/venv/lib/python3.7/site-packages/django/http/response.py", line 552, in __init__
    'In order to allow non-dict objects to be serialized set the '
TypeError: In order to allow non-dict objects to be serialized set the safe parameter to False.
[2019-07-08 12:01:24,783] INFO    : /home/arcturus/Projects/sharewood/app/views_api.py changed, reloading.
[2019-07-08 12:01:39,365] INFO    : /home/arcturus/Projects/sharewood/app/views_api.py changed, reloading.
[2019-07-08 12:01:40,442] WARNING : Not Found: /api/registration
[2019-07-08 12:01:40,952] WARNING : Not Found: /api/registration
[2019-07-08 12:01:41,192] WARNING : Not Found: /api/registration
[2019-07-08 12:02:22,265] INFO    : /home/arcturus/Projects/sharewood/app/views_api.py changed, reloading.
[2019-07-08 12:03:54,791] INFO    : /home/arcturus/Projects/sharewood/app/views_api.py changed, reloading.
[2019-07-08 12:04:04,108] INFO    : /home/arcturus/Projects/sharewood/app/views_api.py changed, reloading.
[2019-07-08 12:05:07,190] INFO    : /home/arcturus/Projects/sharewood/app/views_api.py changed, reloading.
[2019-07-08 12:05:13,237] INFO    : /home/arcturus/Projects/sharewood/app/views_api.py changed, reloading.
[2019-07-08 12:05:30,921] INFO    : /home/arcturus/Projects/sharewood/app/views_api.py changed, reloading.
[2019-07-08 12:05:47,514] INFO    : /home/arcturus/Projects/sharewood/app/views_api.py changed, reloading.
[2019-07-08 12:08:00,766] INFO    : /home/arcturus/Projects/sharewood/app/views.py changed, reloading.
[2019-07-08 12:08:05,629] ERROR   : Internal Server Error: /statistics/
Traceback (most recent call last):
  File "/home/arcturus/Projects/sharewood/venv/lib/python3.7/site-packages/django/core/handlers/exception.py", line 34, in inner
    response = get_response(request)
  File "/home/arcturus/Projects/sharewood/venv/lib/python3.7/site-packages/django/core/handlers/base.py", line 115, in _get_response
    response = self.process_exception_by_middleware(e, request)
  File "/home/arcturus/Projects/sharewood/venv/lib/python3.7/site-packages/django/core/handlers/base.py", line 113, in _get_response
    response = wrapped_callback(request, *callback_args, **callback_kwargs)
  File "/home/arcturus/Projects/sharewood/venv/lib/python3.7/site-packages/django/views/generic/base.py", line 71, in view
    return self.dispatch(request, *args, **kwargs)
  File "/home/arcturus/Projects/sharewood/venv/lib/python3.7/site-packages/django/views/generic/base.py", line 97, in dispatch
    return handler(request, *args, **kwargs)
  File "/home/arcturus/Projects/sharewood/app/views.py", line 573, in get
    return render(request, 'charts.html', {"customers": 10})
  File "/home/arcturus/Projects/sharewood/venv/lib/python3.7/site-packages/django/shortcuts.py", line 36, in render
    content = loader.render_to_string(template_name, context, request, using=using)
  File "/home/arcturus/Projects/sharewood/venv/lib/python3.7/site-packages/django/template/loader.py", line 62, in render_to_string
    return template.render(context, request)
  File "/home/arcturus/Projects/sharewood/venv/lib/python3.7/site-packages/django/template/backends/django.py", line 61, in render
    return self.template.render(context)
  File "/home/arcturus/Projects/sharewood/venv/lib/python3.7/site-packages/django/template/base.py", line 171, in render
    return self._render(context)
  File "/home/arcturus/Projects/sharewood/venv/lib/python3.7/site-packages/django/template/base.py", line 163, in _render
    return self.nodelist.render(context)
  File "/home/arcturus/Projects/sharewood/venv/lib/python3.7/site-packages/django/template/base.py", line 937, in render
    bit = node.render_annotated(context)
  File "/home/arcturus/Projects/sharewood/venv/lib/python3.7/site-packages/django/template/base.py", line 904, in render_annotated
    return self.render(context)
  File "/home/arcturus/Projects/sharewood/venv/lib/python3.7/site-packages/django/template/loader_tags.py", line 150, in render
    return compiled_parent._render(context)
  File "/home/arcturus/Projects/sharewood/venv/lib/python3.7/site-packages/django/template/base.py", line 163, in _render
    return self.nodelist.render(context)
  File "/home/arcturus/Projects/sharewood/venv/lib/python3.7/site-packages/django/template/base.py", line 937, in render
    bit = node.render_annotated(context)
  File "/home/arcturus/Projects/sharewood/venv/lib/python3.7/site-packages/django/template/base.py", line 904, in render_annotated
    return self.render(context)
  File "/home/arcturus/Projects/sharewood/venv/lib/python3.7/site-packages/django/template/loader_tags.py", line 62, in render
    result = block.nodelist.render(context)
  File "/home/arcturus/Projects/sharewood/venv/lib/python3.7/site-packages/django/template/base.py", line 937, in render
    bit = node.render_annotated(context)
  File "/home/arcturus/Projects/sharewood/venv/lib/python3.7/site-packages/django/template/base.py", line 904, in render_annotated
    return self.render(context)
  File "/home/arcturus/Projects/sharewood/venv/lib/python3.7/site-packages/django/template/defaulttags.py", line 443, in render
    url = reverse(view_name, args=args, kwargs=kwargs, current_app=current_app)
  File "/home/arcturus/Projects/sharewood/venv/lib/python3.7/site-packages/django/urls/base.py", line 90, in reverse
    return iri_to_uri(resolver._reverse_with_prefix(view, prefix, *args, **kwargs))
  File "/home/arcturus/Projects/sharewood/venv/lib/python3.7/site-packages/django/urls/resolvers.py", line 668, in _reverse_with_prefix
    raise NoReverseMatch(msg)
django.urls.exceptions.NoReverseMatch: Reverse for 'api-data' with no arguments not found. 1 pattern(s) tried: ['api/(?P<data>[^/]+)$']
[2019-07-08 12:08:51,106] ERROR   : Internal Server Error: /statistics/
Traceback (most recent call last):
  File "/home/arcturus/Projects/sharewood/venv/lib/python3.7/site-packages/django/core/handlers/exception.py", line 34, in inner
    response = get_response(request)
  File "/home/arcturus/Projects/sharewood/venv/lib/python3.7/site-packages/django/core/handlers/base.py", line 115, in _get_response
    response = self.process_exception_by_middleware(e, request)
  File "/home/arcturus/Projects/sharewood/venv/lib/python3.7/site-packages/django/core/handlers/base.py", line 113, in _get_response
    response = wrapped_callback(request, *callback_args, **callback_kwargs)
  File "/home/arcturus/Projects/sharewood/venv/lib/python3.7/site-packages/django/views/generic/base.py", line 71, in view
    return self.dispatch(request, *args, **kwargs)
  File "/home/arcturus/Projects/sharewood/venv/lib/python3.7/site-packages/django/views/generic/base.py", line 97, in dispatch
    return handler(request, *args, **kwargs)
  File "/home/arcturus/Projects/sharewood/app/views.py", line 573, in get
    return render(request, 'charts.html', {"customers": 10})
  File "/home/arcturus/Projects/sharewood/venv/lib/python3.7/site-packages/django/shortcuts.py", line 36, in render
    content = loader.render_to_string(template_name, context, request, using=using)
  File "/home/arcturus/Projects/sharewood/venv/lib/python3.7/site-packages/django/template/loader.py", line 62, in render_to_string
    return template.render(context, request)
  File "/home/arcturus/Projects/sharewood/venv/lib/python3.7/site-packages/django/template/backends/django.py", line 61, in render
    return self.template.render(context)
  File "/home/arcturus/Projects/sharewood/venv/lib/python3.7/site-packages/django/template/base.py", line 171, in render
    return self._render(context)
  File "/home/arcturus/Projects/sharewood/venv/lib/python3.7/site-packages/django/template/base.py", line 163, in _render
    return self.nodelist.render(context)
  File "/home/arcturus/Projects/sharewood/venv/lib/python3.7/site-packages/django/template/base.py", line 937, in render
    bit = node.render_annotated(context)
  File "/home/arcturus/Projects/sharewood/venv/lib/python3.7/site-packages/django/template/base.py", line 904, in render_annotated
    return self.render(context)
  File "/home/arcturus/Projects/sharewood/venv/lib/python3.7/site-packages/django/template/loader_tags.py", line 150, in render
    return compiled_parent._render(context)
  File "/home/arcturus/Projects/sharewood/venv/lib/python3.7/site-packages/django/template/base.py", line 163, in _render
    return self.nodelist.render(context)
  File "/home/arcturus/Projects/sharewood/venv/lib/python3.7/site-packages/django/template/base.py", line 937, in render
    bit = node.render_annotated(context)
  File "/home/arcturus/Projects/sharewood/venv/lib/python3.7/site-packages/django/template/base.py", line 904, in render_annotated
    return self.render(context)
  File "/home/arcturus/Projects/sharewood/venv/lib/python3.7/site-packages/django/template/loader_tags.py", line 62, in render
    result = block.nodelist.render(context)
  File "/home/arcturus/Projects/sharewood/venv/lib/python3.7/site-packages/django/template/base.py", line 937, in render
    bit = node.render_annotated(context)
  File "/home/arcturus/Projects/sharewood/venv/lib/python3.7/site-packages/django/template/base.py", line 904, in render_annotated
    return self.render(context)
  File "/home/arcturus/Projects/sharewood/venv/lib/python3.7/site-packages/django/template/defaulttags.py", line 443, in render
    url = reverse(view_name, args=args, kwargs=kwargs, current_app=current_app)
  File "/home/arcturus/Projects/sharewood/venv/lib/python3.7/site-packages/django/urls/base.py", line 90, in reverse
    return iri_to_uri(resolver._reverse_with_prefix(view, prefix, *args, **kwargs))
  File "/home/arcturus/Projects/sharewood/venv/lib/python3.7/site-packages/django/urls/resolvers.py", line 668, in _reverse_with_prefix
    raise NoReverseMatch(msg)
django.urls.exceptions.NoReverseMatch: Reverse for 'api' not found. 'api' is not a valid view function or pattern name.
[2019-07-08 12:08:51,208] WARNING : Not Found: /favicon.ico
[2019-07-08 12:08:51,709] ERROR   : Internal Server Error: /statistics/
Traceback (most recent call last):
  File "/home/arcturus/Projects/sharewood/venv/lib/python3.7/site-packages/django/core/handlers/exception.py", line 34, in inner
    response = get_response(request)
  File "/home/arcturus/Projects/sharewood/venv/lib/python3.7/site-packages/django/core/handlers/base.py", line 115, in _get_response
    response = self.process_exception_by_middleware(e, request)
  File "/home/arcturus/Projects/sharewood/venv/lib/python3.7/site-packages/django/core/handlers/base.py", line 113, in _get_response
    response = wrapped_callback(request, *callback_args, **callback_kwargs)
  File "/home/arcturus/Projects/sharewood/venv/lib/python3.7/site-packages/django/views/generic/base.py", line 71, in view
    return self.dispatch(request, *args, **kwargs)
  File "/home/arcturus/Projects/sharewood/venv/lib/python3.7/site-packages/django/views/generic/base.py", line 97, in dispatch
    return handler(request, *args, **kwargs)
  File "/home/arcturus/Projects/sharewood/app/views.py", line 573, in get
    return render(request, 'charts.html', {"customers": 10})
  File "/home/arcturus/Projects/sharewood/venv/lib/python3.7/site-packages/django/shortcuts.py", line 36, in render
    content = loader.render_to_string(template_name, context, request, using=using)
  File "/home/arcturus/Projects/sharewood/venv/lib/python3.7/site-packages/django/template/loader.py", line 62, in render_to_string
    return template.render(context, request)
  File "/home/arcturus/Projects/sharewood/venv/lib/python3.7/site-packages/django/template/backends/django.py", line 61, in render
    return self.template.render(context)
  File "/home/arcturus/Projects/sharewood/venv/lib/python3.7/site-packages/django/template/base.py", line 171, in render
    return self._render(context)
  File "/home/arcturus/Projects/sharewood/venv/lib/python3.7/site-packages/django/template/base.py", line 163, in _render
    return self.nodelist.render(context)
  File "/home/arcturus/Projects/sharewood/venv/lib/python3.7/site-packages/django/template/base.py", line 937, in render
    bit = node.render_annotated(context)
  File "/home/arcturus/Projects/sharewood/venv/lib/python3.7/site-packages/django/template/base.py", line 904, in render_annotated
    return self.render(context)
  File "/home/arcturus/Projects/sharewood/venv/lib/python3.7/site-packages/django/template/loader_tags.py", line 150, in render
    return compiled_parent._render(context)
  File "/home/arcturus/Projects/sharewood/venv/lib/python3.7/site-packages/django/template/base.py", line 163, in _render
    return self.nodelist.render(context)
  File "/home/arcturus/Projects/sharewood/venv/lib/python3.7/site-packages/django/template/base.py", line 937, in render
    bit = node.render_annotated(context)
  File "/home/arcturus/Projects/sharewood/venv/lib/python3.7/site-packages/django/template/base.py", line 904, in render_annotated
    return self.render(context)
  File "/home/arcturus/Projects/sharewood/venv/lib/python3.7/site-packages/django/template/loader_tags.py", line 62, in render
    result = block.nodelist.render(context)
  File "/home/arcturus/Projects/sharewood/venv/lib/python3.7/site-packages/django/template/base.py", line 937, in render
    bit = node.render_annotated(context)
  File "/home/arcturus/Projects/sharewood/venv/lib/python3.7/site-packages/django/template/base.py", line 904, in render_annotated
    return self.render(context)
  File "/home/arcturus/Projects/sharewood/venv/lib/python3.7/site-packages/django/template/defaulttags.py", line 443, in render
    url = reverse(view_name, args=args, kwargs=kwargs, current_app=current_app)
  File "/home/arcturus/Projects/sharewood/venv/lib/python3.7/site-packages/django/urls/base.py", line 90, in reverse
    return iri_to_uri(resolver._reverse_with_prefix(view, prefix, *args, **kwargs))
  File "/home/arcturus/Projects/sharewood/venv/lib/python3.7/site-packages/django/urls/resolvers.py", line 668, in _reverse_with_prefix
    raise NoReverseMatch(msg)
django.urls.exceptions.NoReverseMatch: Reverse for 'api' not found. 'api' is not a valid view function or pattern name.
[2019-07-08 12:08:52,278] ERROR   : Internal Server Error: /statistics/
Traceback (most recent call last):
  File "/home/arcturus/Projects/sharewood/venv/lib/python3.7/site-packages/django/core/handlers/exception.py", line 34, in inner
    response = get_response(request)
  File "/home/arcturus/Projects/sharewood/venv/lib/python3.7/site-packages/django/core/handlers/base.py", line 115, in _get_response
    response = self.process_exception_by_middleware(e, request)
  File "/home/arcturus/Projects/sharewood/venv/lib/python3.7/site-packages/django/core/handlers/base.py", line 113, in _get_response
    response = wrapped_callback(request, *callback_args, **callback_kwargs)
  File "/home/arcturus/Projects/sharewood/venv/lib/python3.7/site-packages/django/views/generic/base.py", line 71, in view
    return self.dispatch(request, *args, **kwargs)
  File "/home/arcturus/Projects/sharewood/venv/lib/python3.7/site-packages/django/views/generic/base.py", line 97, in dispatch
    return handler(request, *args, **kwargs)
  File "/home/arcturus/Projects/sharewood/app/views.py", line 573, in get
    return render(request, 'charts.html', {"customers": 10})
  File "/home/arcturus/Projects/sharewood/venv/lib/python3.7/site-packages/django/shortcuts.py", line 36, in render
    content = loader.render_to_string(template_name, context, request, using=using)
  File "/home/arcturus/Projects/sharewood/venv/lib/python3.7/site-packages/django/template/loader.py", line 62, in render_to_string
    return template.render(context, request)
  File "/home/arcturus/Projects/sharewood/venv/lib/python3.7/site-packages/django/template/backends/django.py", line 61, in render
    return self.template.render(context)
  File "/home/arcturus/Projects/sharewood/venv/lib/python3.7/site-packages/django/template/base.py", line 171, in render
    return self._render(context)
  File "/home/arcturus/Projects/sharewood/venv/lib/python3.7/site-packages/django/template/base.py", line 163, in _render
    return self.nodelist.render(context)
  File "/home/arcturus/Projects/sharewood/venv/lib/python3.7/site-packages/django/template/base.py", line 937, in render
    bit = node.render_annotated(context)
  File "/home/arcturus/Projects/sharewood/venv/lib/python3.7/site-packages/django/template/base.py", line 904, in render_annotated
    return self.render(context)
  File "/home/arcturus/Projects/sharewood/venv/lib/python3.7/site-packages/django/template/loader_tags.py", line 150, in render
    return compiled_parent._render(context)
  File "/home/arcturus/Projects/sharewood/venv/lib/python3.7/site-packages/django/template/base.py", line 163, in _render
    return self.nodelist.render(context)
  File "/home/arcturus/Projects/sharewood/venv/lib/python3.7/site-packages/django/template/base.py", line 937, in render
    bit = node.render_annotated(context)
  File "/home/arcturus/Projects/sharewood/venv/lib/python3.7/site-packages/django/template/base.py", line 904, in render_annotated
    return self.render(context)
  File "/home/arcturus/Projects/sharewood/venv/lib/python3.7/site-packages/django/template/loader_tags.py", line 62, in render
    result = block.nodelist.render(context)
  File "/home/arcturus/Projects/sharewood/venv/lib/python3.7/site-packages/django/template/base.py", line 937, in render
    bit = node.render_annotated(context)
  File "/home/arcturus/Projects/sharewood/venv/lib/python3.7/site-packages/django/template/base.py", line 904, in render_annotated
    return self.render(context)
  File "/home/arcturus/Projects/sharewood/venv/lib/python3.7/site-packages/django/template/defaulttags.py", line 443, in render
    url = reverse(view_name, args=args, kwargs=kwargs, current_app=current_app)
  File "/home/arcturus/Projects/sharewood/venv/lib/python3.7/site-packages/django/urls/base.py", line 90, in reverse
    return iri_to_uri(resolver._reverse_with_prefix(view, prefix, *args, **kwargs))
  File "/home/arcturus/Projects/sharewood/venv/lib/python3.7/site-packages/django/urls/resolvers.py", line 668, in _reverse_with_prefix
    raise NoReverseMatch(msg)
django.urls.exceptions.NoReverseMatch: Reverse for 'api' not found. 'api' is not a valid view function or pattern name.
[2019-07-08 12:08:52,307] WARNING : Not Found: /favicon.ico
[2019-07-08 12:09:01,459] ERROR   : Internal Server Error: /statistics/
Traceback (most recent call last):
  File "/home/arcturus/Projects/sharewood/venv/lib/python3.7/site-packages/django/core/handlers/exception.py", line 34, in inner
    response = get_response(request)
  File "/home/arcturus/Projects/sharewood/venv/lib/python3.7/site-packages/django/core/handlers/base.py", line 115, in _get_response
    response = self.process_exception_by_middleware(e, request)
  File "/home/arcturus/Projects/sharewood/venv/lib/python3.7/site-packages/django/core/handlers/base.py", line 113, in _get_response
    response = wrapped_callback(request, *callback_args, **callback_kwargs)
  File "/home/arcturus/Projects/sharewood/venv/lib/python3.7/site-packages/django/views/generic/base.py", line 71, in view
    return self.dispatch(request, *args, **kwargs)
  File "/home/arcturus/Projects/sharewood/venv/lib/python3.7/site-packages/django/views/generic/base.py", line 97, in dispatch
    return handler(request, *args, **kwargs)
  File "/home/arcturus/Projects/sharewood/app/views.py", line 573, in get
    return render(request, 'charts.html', {"customers": 10})
  File "/home/arcturus/Projects/sharewood/venv/lib/python3.7/site-packages/django/shortcuts.py", line 36, in render
    content = loader.render_to_string(template_name, context, request, using=using)
  File "/home/arcturus/Projects/sharewood/venv/lib/python3.7/site-packages/django/template/loader.py", line 62, in render_to_string
    return template.render(context, request)
  File "/home/arcturus/Projects/sharewood/venv/lib/python3.7/site-packages/django/template/backends/django.py", line 61, in render
    return self.template.render(context)
  File "/home/arcturus/Projects/sharewood/venv/lib/python3.7/site-packages/django/template/base.py", line 171, in render
    return self._render(context)
  File "/home/arcturus/Projects/sharewood/venv/lib/python3.7/site-packages/django/template/base.py", line 163, in _render
    return self.nodelist.render(context)
  File "/home/arcturus/Projects/sharewood/venv/lib/python3.7/site-packages/django/template/base.py", line 937, in render
    bit = node.render_annotated(context)
  File "/home/arcturus/Projects/sharewood/venv/lib/python3.7/site-packages/django/template/base.py", line 904, in render_annotated
    return self.render(context)
  File "/home/arcturus/Projects/sharewood/venv/lib/python3.7/site-packages/django/template/loader_tags.py", line 150, in render
    return compiled_parent._render(context)
  File "/home/arcturus/Projects/sharewood/venv/lib/python3.7/site-packages/django/template/base.py", line 163, in _render
    return self.nodelist.render(context)
  File "/home/arcturus/Projects/sharewood/venv/lib/python3.7/site-packages/django/template/base.py", line 937, in render
    bit = node.render_annotated(context)
  File "/home/arcturus/Projects/sharewood/venv/lib/python3.7/site-packages/django/template/base.py", line 904, in render_annotated
    return self.render(context)
  File "/home/arcturus/Projects/sharewood/venv/lib/python3.7/site-packages/django/template/loader_tags.py", line 62, in render
    result = block.nodelist.render(context)
  File "/home/arcturus/Projects/sharewood/venv/lib/python3.7/site-packages/django/template/base.py", line 937, in render
    bit = node.render_annotated(context)
  File "/home/arcturus/Projects/sharewood/venv/lib/python3.7/site-packages/django/template/base.py", line 904, in render_annotated
    return self.render(context)
  File "/home/arcturus/Projects/sharewood/venv/lib/python3.7/site-packages/django/template/defaulttags.py", line 443, in render
    url = reverse(view_name, args=args, kwargs=kwargs, current_app=current_app)
  File "/home/arcturus/Projects/sharewood/venv/lib/python3.7/site-packages/django/urls/base.py", line 90, in reverse
    return iri_to_uri(resolver._reverse_with_prefix(view, prefix, *args, **kwargs))
  File "/home/arcturus/Projects/sharewood/venv/lib/python3.7/site-packages/django/urls/resolvers.py", line 668, in _reverse_with_prefix
    raise NoReverseMatch(msg)
django.urls.exceptions.NoReverseMatch: Reverse for 'api-data' with no arguments not found. 1 pattern(s) tried: ['api/(?P<data>[^/]+)$']
[2019-07-08 12:09:01,999] ERROR   : Internal Server Error: /statistics/
Traceback (most recent call last):
  File "/home/arcturus/Projects/sharewood/venv/lib/python3.7/site-packages/django/core/handlers/exception.py", line 34, in inner
    response = get_response(request)
  File "/home/arcturus/Projects/sharewood/venv/lib/python3.7/site-packages/django/core/handlers/base.py", line 115, in _get_response
    response = self.process_exception_by_middleware(e, request)
  File "/home/arcturus/Projects/sharewood/venv/lib/python3.7/site-packages/django/core/handlers/base.py", line 113, in _get_response
    response = wrapped_callback(request, *callback_args, **callback_kwargs)
  File "/home/arcturus/Projects/sharewood/venv/lib/python3.7/site-packages/django/views/generic/base.py", line 71, in view
    return self.dispatch(request, *args, **kwargs)
  File "/home/arcturus/Projects/sharewood/venv/lib/python3.7/site-packages/django/views/generic/base.py", line 97, in dispatch
    return handler(request, *args, **kwargs)
  File "/home/arcturus/Projects/sharewood/app/views.py", line 573, in get
    return render(request, 'charts.html', {"customers": 10})
  File "/home/arcturus/Projects/sharewood/venv/lib/python3.7/site-packages/django/shortcuts.py", line 36, in render
    content = loader.render_to_string(template_name, context, request, using=using)
  File "/home/arcturus/Projects/sharewood/venv/lib/python3.7/site-packages/django/template/loader.py", line 62, in render_to_string
    return template.render(context, request)
  File "/home/arcturus/Projects/sharewood/venv/lib/python3.7/site-packages/django/template/backends/django.py", line 61, in render
    return self.template.render(context)
  File "/home/arcturus/Projects/sharewood/venv/lib/python3.7/site-packages/django/template/base.py", line 171, in render
    return self._render(context)
  File "/home/arcturus/Projects/sharewood/venv/lib/python3.7/site-packages/django/template/base.py", line 163, in _render
    return self.nodelist.render(context)
  File "/home/arcturus/Projects/sharewood/venv/lib/python3.7/site-packages/django/template/base.py", line 937, in render
    bit = node.render_annotated(context)
  File "/home/arcturus/Projects/sharewood/venv/lib/python3.7/site-packages/django/template/base.py", line 904, in render_annotated
    return self.render(context)
  File "/home/arcturus/Projects/sharewood/venv/lib/python3.7/site-packages/django/template/loader_tags.py", line 150, in render
    return compiled_parent._render(context)
  File "/home/arcturus/Projects/sharewood/venv/lib/python3.7/site-packages/django/template/base.py", line 163, in _render
    return self.nodelist.render(context)
  File "/home/arcturus/Projects/sharewood/venv/lib/python3.7/site-packages/django/template/base.py", line 937, in render
    bit = node.render_annotated(context)
  File "/home/arcturus/Projects/sharewood/venv/lib/python3.7/site-packages/django/template/base.py", line 904, in render_annotated
    return self.render(context)
  File "/home/arcturus/Projects/sharewood/venv/lib/python3.7/site-packages/django/template/loader_tags.py", line 62, in render
    result = block.nodelist.render(context)
  File "/home/arcturus/Projects/sharewood/venv/lib/python3.7/site-packages/django/template/base.py", line 937, in render
    bit = node.render_annotated(context)
  File "/home/arcturus/Projects/sharewood/venv/lib/python3.7/site-packages/django/template/base.py", line 904, in render_annotated
    return self.render(context)
  File "/home/arcturus/Projects/sharewood/venv/lib/python3.7/site-packages/django/template/defaulttags.py", line 443, in render
    url = reverse(view_name, args=args, kwargs=kwargs, current_app=current_app)
  File "/home/arcturus/Projects/sharewood/venv/lib/python3.7/site-packages/django/urls/base.py", line 90, in reverse
    return iri_to_uri(resolver._reverse_with_prefix(view, prefix, *args, **kwargs))
  File "/home/arcturus/Projects/sharewood/venv/lib/python3.7/site-packages/django/urls/resolvers.py", line 668, in _reverse_with_prefix
    raise NoReverseMatch(msg)
django.urls.exceptions.NoReverseMatch: Reverse for 'api-data' with no arguments not found. 1 pattern(s) tried: ['api/(?P<data>[^/]+)$']
[2019-07-08 12:09:02,434] ERROR   : Internal Server Error: /statistics/
Traceback (most recent call last):
  File "/home/arcturus/Projects/sharewood/venv/lib/python3.7/site-packages/django/core/handlers/exception.py", line 34, in inner
    response = get_response(request)
  File "/home/arcturus/Projects/sharewood/venv/lib/python3.7/site-packages/django/core/handlers/base.py", line 115, in _get_response
    response = self.process_exception_by_middleware(e, request)
  File "/home/arcturus/Projects/sharewood/venv/lib/python3.7/site-packages/django/core/handlers/base.py", line 113, in _get_response
    response = wrapped_callback(request, *callback_args, **callback_kwargs)
  File "/home/arcturus/Projects/sharewood/venv/lib/python3.7/site-packages/django/views/generic/base.py", line 71, in view
    return self.dispatch(request, *args, **kwargs)
  File "/home/arcturus/Projects/sharewood/venv/lib/python3.7/site-packages/django/views/generic/base.py", line 97, in dispatch
    return handler(request, *args, **kwargs)
  File "/home/arcturus/Projects/sharewood/app/views.py", line 573, in get
    return render(request, 'charts.html', {"customers": 10})
  File "/home/arcturus/Projects/sharewood/venv/lib/python3.7/site-packages/django/shortcuts.py", line 36, in render
    content = loader.render_to_string(template_name, context, request, using=using)
  File "/home/arcturus/Projects/sharewood/venv/lib/python3.7/site-packages/django/template/loader.py", line 62, in render_to_string
    return template.render(context, request)
  File "/home/arcturus/Projects/sharewood/venv/lib/python3.7/site-packages/django/template/backends/django.py", line 61, in render
    return self.template.render(context)
  File "/home/arcturus/Projects/sharewood/venv/lib/python3.7/site-packages/django/template/base.py", line 171, in render
    return self._render(context)
  File "/home/arcturus/Projects/sharewood/venv/lib/python3.7/site-packages/django/template/base.py", line 163, in _render
    return self.nodelist.render(context)
  File "/home/arcturus/Projects/sharewood/venv/lib/python3.7/site-packages/django/template/base.py", line 937, in render
    bit = node.render_annotated(context)
  File "/home/arcturus/Projects/sharewood/venv/lib/python3.7/site-packages/django/template/base.py", line 904, in render_annotated
    return self.render(context)
  File "/home/arcturus/Projects/sharewood/venv/lib/python3.7/site-packages/django/template/loader_tags.py", line 150, in render
    return compiled_parent._render(context)
  File "/home/arcturus/Projects/sharewood/venv/lib/python3.7/site-packages/django/template/base.py", line 163, in _render
    return self.nodelist.render(context)
  File "/home/arcturus/Projects/sharewood/venv/lib/python3.7/site-packages/django/template/base.py", line 937, in render
    bit = node.render_annotated(context)
  File "/home/arcturus/Projects/sharewood/venv/lib/python3.7/site-packages/django/template/base.py", line 904, in render_annotated
    return self.render(context)
  File "/home/arcturus/Projects/sharewood/venv/lib/python3.7/site-packages/django/template/loader_tags.py", line 62, in render
    result = block.nodelist.render(context)
  File "/home/arcturus/Projects/sharewood/venv/lib/python3.7/site-packages/django/template/base.py", line 937, in render
    bit = node.render_annotated(context)
  File "/home/arcturus/Projects/sharewood/venv/lib/python3.7/site-packages/django/template/base.py", line 904, in render_annotated
    return self.render(context)
  File "/home/arcturus/Projects/sharewood/venv/lib/python3.7/site-packages/django/template/defaulttags.py", line 443, in render
    url = reverse(view_name, args=args, kwargs=kwargs, current_app=current_app)
  File "/home/arcturus/Projects/sharewood/venv/lib/python3.7/site-packages/django/urls/base.py", line 90, in reverse
    return iri_to_uri(resolver._reverse_with_prefix(view, prefix, *args, **kwargs))
  File "/home/arcturus/Projects/sharewood/venv/lib/python3.7/site-packages/django/urls/resolvers.py", line 668, in _reverse_with_prefix
    raise NoReverseMatch(msg)
django.urls.exceptions.NoReverseMatch: Reverse for 'api-data' with no arguments not found. 1 pattern(s) tried: ['api/(?P<data>[^/]+)$']
[2019-07-08 12:09:02,499] WARNING : Not Found: /favicon.ico
[2019-07-08 12:12:12,601] ERROR   : Internal Server Error: /statistics/
Traceback (most recent call last):
  File "/home/arcturus/Projects/sharewood/venv/lib/python3.7/site-packages/django/core/handlers/exception.py", line 34, in inner
    response = get_response(request)
  File "/home/arcturus/Projects/sharewood/venv/lib/python3.7/site-packages/django/core/handlers/base.py", line 115, in _get_response
    response = self.process_exception_by_middleware(e, request)
  File "/home/arcturus/Projects/sharewood/venv/lib/python3.7/site-packages/django/core/handlers/base.py", line 113, in _get_response
    response = wrapped_callback(request, *callback_args, **callback_kwargs)
  File "/home/arcturus/Projects/sharewood/venv/lib/python3.7/site-packages/django/views/generic/base.py", line 71, in view
    return self.dispatch(request, *args, **kwargs)
  File "/home/arcturus/Projects/sharewood/venv/lib/python3.7/site-packages/django/views/generic/base.py", line 97, in dispatch
    return handler(request, *args, **kwargs)
  File "/home/arcturus/Projects/sharewood/app/views.py", line 573, in get
    return render(request, 'charts.html', {"customers": 10})
  File "/home/arcturus/Projects/sharewood/venv/lib/python3.7/site-packages/django/shortcuts.py", line 36, in render
    content = loader.render_to_string(template_name, context, request, using=using)
  File "/home/arcturus/Projects/sharewood/venv/lib/python3.7/site-packages/django/template/loader.py", line 62, in render_to_string
    return template.render(context, request)
  File "/home/arcturus/Projects/sharewood/venv/lib/python3.7/site-packages/django/template/backends/django.py", line 61, in render
    return self.template.render(context)
  File "/home/arcturus/Projects/sharewood/venv/lib/python3.7/site-packages/django/template/base.py", line 171, in render
    return self._render(context)
  File "/home/arcturus/Projects/sharewood/venv/lib/python3.7/site-packages/django/template/base.py", line 163, in _render
    return self.nodelist.render(context)
  File "/home/arcturus/Projects/sharewood/venv/lib/python3.7/site-packages/django/template/base.py", line 937, in render
    bit = node.render_annotated(context)
  File "/home/arcturus/Projects/sharewood/venv/lib/python3.7/site-packages/django/template/base.py", line 904, in render_annotated
    return self.render(context)
  File "/home/arcturus/Projects/sharewood/venv/lib/python3.7/site-packages/django/template/loader_tags.py", line 150, in render
    return compiled_parent._render(context)
  File "/home/arcturus/Projects/sharewood/venv/lib/python3.7/site-packages/django/template/base.py", line 163, in _render
    return self.nodelist.render(context)
  File "/home/arcturus/Projects/sharewood/venv/lib/python3.7/site-packages/django/template/base.py", line 937, in render
    bit = node.render_annotated(context)
  File "/home/arcturus/Projects/sharewood/venv/lib/python3.7/site-packages/django/template/base.py", line 904, in render_annotated
    return self.render(context)
  File "/home/arcturus/Projects/sharewood/venv/lib/python3.7/site-packages/django/template/loader_tags.py", line 62, in render
    result = block.nodelist.render(context)
  File "/home/arcturus/Projects/sharewood/venv/lib/python3.7/site-packages/django/template/base.py", line 937, in render
    bit = node.render_annotated(context)
  File "/home/arcturus/Projects/sharewood/venv/lib/python3.7/site-packages/django/template/base.py", line 904, in render_annotated
    return self.render(context)
  File "/home/arcturus/Projects/sharewood/venv/lib/python3.7/site-packages/django/template/defaulttags.py", line 443, in render
    url = reverse(view_name, args=args, kwargs=kwargs, current_app=current_app)
  File "/home/arcturus/Projects/sharewood/venv/lib/python3.7/site-packages/django/urls/base.py", line 90, in reverse
    return iri_to_uri(resolver._reverse_with_prefix(view, prefix, *args, **kwargs))
  File "/home/arcturus/Projects/sharewood/venv/lib/python3.7/site-packages/django/urls/resolvers.py", line 668, in _reverse_with_prefix
    raise NoReverseMatch(msg)
django.urls.exceptions.NoReverseMatch: Reverse for 'api-data' with no arguments not found. 1 pattern(s) tried: ['api/(?P<data>[^/]+)$']
[2019-07-08 12:12:12,667] WARNING : Not Found: /favicon.ico
[2019-07-08 12:12:13,205] ERROR   : Internal Server Error: /statistics/
Traceback (most recent call last):
  File "/home/arcturus/Projects/sharewood/venv/lib/python3.7/site-packages/django/core/handlers/exception.py", line 34, in inner
    response = get_response(request)
  File "/home/arcturus/Projects/sharewood/venv/lib/python3.7/site-packages/django/core/handlers/base.py", line 115, in _get_response
    response = self.process_exception_by_middleware(e, request)
  File "/home/arcturus/Projects/sharewood/venv/lib/python3.7/site-packages/django/core/handlers/base.py", line 113, in _get_response
    response = wrapped_callback(request, *callback_args, **callback_kwargs)
  File "/home/arcturus/Projects/sharewood/venv/lib/python3.7/site-packages/django/views/generic/base.py", line 71, in view
    return self.dispatch(request, *args, **kwargs)
  File "/home/arcturus/Projects/sharewood/venv/lib/python3.7/site-packages/django/views/generic/base.py", line 97, in dispatch
    return handler(request, *args, **kwargs)
  File "/home/arcturus/Projects/sharewood/app/views.py", line 573, in get
    return render(request, 'charts.html', {"customers": 10})
  File "/home/arcturus/Projects/sharewood/venv/lib/python3.7/site-packages/django/shortcuts.py", line 36, in render
    content = loader.render_to_string(template_name, context, request, using=using)
  File "/home/arcturus/Projects/sharewood/venv/lib/python3.7/site-packages/django/template/loader.py", line 62, in render_to_string
    return template.render(context, request)
  File "/home/arcturus/Projects/sharewood/venv/lib/python3.7/site-packages/django/template/backends/django.py", line 61, in render
    return self.template.render(context)
  File "/home/arcturus/Projects/sharewood/venv/lib/python3.7/site-packages/django/template/base.py", line 171, in render
    return self._render(context)
  File "/home/arcturus/Projects/sharewood/venv/lib/python3.7/site-packages/django/template/base.py", line 163, in _render
    return self.nodelist.render(context)
  File "/home/arcturus/Projects/sharewood/venv/lib/python3.7/site-packages/django/template/base.py", line 937, in render
    bit = node.render_annotated(context)
  File "/home/arcturus/Projects/sharewood/venv/lib/python3.7/site-packages/django/template/base.py", line 904, in render_annotated
    return self.render(context)
  File "/home/arcturus/Projects/sharewood/venv/lib/python3.7/site-packages/django/template/loader_tags.py", line 150, in render
    return compiled_parent._render(context)
  File "/home/arcturus/Projects/sharewood/venv/lib/python3.7/site-packages/django/template/base.py", line 163, in _render
    return self.nodelist.render(context)
  File "/home/arcturus/Projects/sharewood/venv/lib/python3.7/site-packages/django/template/base.py", line 937, in render
    bit = node.render_annotated(context)
  File "/home/arcturus/Projects/sharewood/venv/lib/python3.7/site-packages/django/template/base.py", line 904, in render_annotated
    return self.render(context)
  File "/home/arcturus/Projects/sharewood/venv/lib/python3.7/site-packages/django/template/loader_tags.py", line 62, in render
    result = block.nodelist.render(context)
  File "/home/arcturus/Projects/sharewood/venv/lib/python3.7/site-packages/django/template/base.py", line 937, in render
    bit = node.render_annotated(context)
  File "/home/arcturus/Projects/sharewood/venv/lib/python3.7/site-packages/django/template/base.py", line 904, in render_annotated
    return self.render(context)
  File "/home/arcturus/Projects/sharewood/venv/lib/python3.7/site-packages/django/template/defaulttags.py", line 443, in render
    url = reverse(view_name, args=args, kwargs=kwargs, current_app=current_app)
  File "/home/arcturus/Projects/sharewood/venv/lib/python3.7/site-packages/django/urls/base.py", line 90, in reverse
    return iri_to_uri(resolver._reverse_with_prefix(view, prefix, *args, **kwargs))
  File "/home/arcturus/Projects/sharewood/venv/lib/python3.7/site-packages/django/urls/resolvers.py", line 668, in _reverse_with_prefix
    raise NoReverseMatch(msg)
django.urls.exceptions.NoReverseMatch: Reverse for 'api-data' with no arguments not found. 1 pattern(s) tried: ['api/(?P<data>[^/]+)$']
[2019-07-08 12:15:00,579] INFO    : /home/arcturus/Projects/sharewood/app/urls.py changed, reloading.
[2019-07-08 12:15:26,207] ERROR   : Internal Server Error: /statistics/
Traceback (most recent call last):
  File "/home/arcturus/Projects/sharewood/venv/lib/python3.7/site-packages/django/core/handlers/exception.py", line 34, in inner
    response = get_response(request)
  File "/home/arcturus/Projects/sharewood/venv/lib/python3.7/site-packages/django/core/handlers/base.py", line 115, in _get_response
    response = self.process_exception_by_middleware(e, request)
  File "/home/arcturus/Projects/sharewood/venv/lib/python3.7/site-packages/django/core/handlers/base.py", line 113, in _get_response
    response = wrapped_callback(request, *callback_args, **callback_kwargs)
  File "/home/arcturus/Projects/sharewood/app/views.py", line 523, in statistics
    return django.shortcuts.render(request, 'charts.html', {"customers": 10})
  File "/home/arcturus/Projects/sharewood/venv/lib/python3.7/site-packages/django/shortcuts.py", line 36, in render
    content = loader.render_to_string(template_name, context, request, using=using)
  File "/home/arcturus/Projects/sharewood/venv/lib/python3.7/site-packages/django/template/loader.py", line 62, in render_to_string
    return template.render(context, request)
  File "/home/arcturus/Projects/sharewood/venv/lib/python3.7/site-packages/django/template/backends/django.py", line 61, in render
    return self.template.render(context)
  File "/home/arcturus/Projects/sharewood/venv/lib/python3.7/site-packages/django/template/base.py", line 171, in render
    return self._render(context)
  File "/home/arcturus/Projects/sharewood/venv/lib/python3.7/site-packages/django/template/base.py", line 163, in _render
    return self.nodelist.render(context)
  File "/home/arcturus/Projects/sharewood/venv/lib/python3.7/site-packages/django/template/base.py", line 937, in render
    bit = node.render_annotated(context)
  File "/home/arcturus/Projects/sharewood/venv/lib/python3.7/site-packages/django/template/base.py", line 904, in render_annotated
    return self.render(context)
  File "/home/arcturus/Projects/sharewood/venv/lib/python3.7/site-packages/django/template/loader_tags.py", line 150, in render
    return compiled_parent._render(context)
  File "/home/arcturus/Projects/sharewood/venv/lib/python3.7/site-packages/django/template/base.py", line 163, in _render
    return self.nodelist.render(context)
  File "/home/arcturus/Projects/sharewood/venv/lib/python3.7/site-packages/django/template/base.py", line 937, in render
    bit = node.render_annotated(context)
  File "/home/arcturus/Projects/sharewood/venv/lib/python3.7/site-packages/django/template/base.py", line 904, in render_annotated
    return self.render(context)
  File "/home/arcturus/Projects/sharewood/venv/lib/python3.7/site-packages/django/template/loader_tags.py", line 62, in render
    result = block.nodelist.render(context)
  File "/home/arcturus/Projects/sharewood/venv/lib/python3.7/site-packages/django/template/base.py", line 937, in render
    bit = node.render_annotated(context)
  File "/home/arcturus/Projects/sharewood/venv/lib/python3.7/site-packages/django/template/base.py", line 904, in render_annotated
    return self.render(context)
  File "/home/arcturus/Projects/sharewood/venv/lib/python3.7/site-packages/django/template/defaulttags.py", line 443, in render
    url = reverse(view_name, args=args, kwargs=kwargs, current_app=current_app)
  File "/home/arcturus/Projects/sharewood/venv/lib/python3.7/site-packages/django/urls/base.py", line 90, in reverse
    return iri_to_uri(resolver._reverse_with_prefix(view, prefix, *args, **kwargs))
  File "/home/arcturus/Projects/sharewood/venv/lib/python3.7/site-packages/django/urls/resolvers.py", line 668, in _reverse_with_prefix
    raise NoReverseMatch(msg)
django.urls.exceptions.NoReverseMatch: Reverse for 'api-data' with no arguments not found. 1 pattern(s) tried: ['api/(?P<data>[^/]+)$']
[2019-07-08 12:15:26,240] WARNING : Not Found: /favicon.ico
[2019-07-08 12:15:26,855] ERROR   : Internal Server Error: /statistics/
Traceback (most recent call last):
  File "/home/arcturus/Projects/sharewood/venv/lib/python3.7/site-packages/django/core/handlers/exception.py", line 34, in inner
    response = get_response(request)
  File "/home/arcturus/Projects/sharewood/venv/lib/python3.7/site-packages/django/core/handlers/base.py", line 115, in _get_response
    response = self.process_exception_by_middleware(e, request)
  File "/home/arcturus/Projects/sharewood/venv/lib/python3.7/site-packages/django/core/handlers/base.py", line 113, in _get_response
    response = wrapped_callback(request, *callback_args, **callback_kwargs)
  File "/home/arcturus/Projects/sharewood/app/views.py", line 523, in statistics
    return django.shortcuts.render(request, 'charts.html', {"customers": 10})
  File "/home/arcturus/Projects/sharewood/venv/lib/python3.7/site-packages/django/shortcuts.py", line 36, in render
    content = loader.render_to_string(template_name, context, request, using=using)
  File "/home/arcturus/Projects/sharewood/venv/lib/python3.7/site-packages/django/template/loader.py", line 62, in render_to_string
    return template.render(context, request)
  File "/home/arcturus/Projects/sharewood/venv/lib/python3.7/site-packages/django/template/backends/django.py", line 61, in render
    return self.template.render(context)
  File "/home/arcturus/Projects/sharewood/venv/lib/python3.7/site-packages/django/template/base.py", line 171, in render
    return self._render(context)
  File "/home/arcturus/Projects/sharewood/venv/lib/python3.7/site-packages/django/template/base.py", line 163, in _render
    return self.nodelist.render(context)
  File "/home/arcturus/Projects/sharewood/venv/lib/python3.7/site-packages/django/template/base.py", line 937, in render
    bit = node.render_annotated(context)
  File "/home/arcturus/Projects/sharewood/venv/lib/python3.7/site-packages/django/template/base.py", line 904, in render_annotated
    return self.render(context)
  File "/home/arcturus/Projects/sharewood/venv/lib/python3.7/site-packages/django/template/loader_tags.py", line 150, in render
    return compiled_parent._render(context)
  File "/home/arcturus/Projects/sharewood/venv/lib/python3.7/site-packages/django/template/base.py", line 163, in _render
    return self.nodelist.render(context)
  File "/home/arcturus/Projects/sharewood/venv/lib/python3.7/site-packages/django/template/base.py", line 937, in render
    bit = node.render_annotated(context)
  File "/home/arcturus/Projects/sharewood/venv/lib/python3.7/site-packages/django/template/base.py", line 904, in render_annotated
    return self.render(context)
  File "/home/arcturus/Projects/sharewood/venv/lib/python3.7/site-packages/django/template/loader_tags.py", line 62, in render
    result = block.nodelist.render(context)
  File "/home/arcturus/Projects/sharewood/venv/lib/python3.7/site-packages/django/template/base.py", line 937, in render
    bit = node.render_annotated(context)
  File "/home/arcturus/Projects/sharewood/venv/lib/python3.7/site-packages/django/template/base.py", line 904, in render_annotated
    return self.render(context)
  File "/home/arcturus/Projects/sharewood/venv/lib/python3.7/site-packages/django/template/defaulttags.py", line 443, in render
    url = reverse(view_name, args=args, kwargs=kwargs, current_app=current_app)
  File "/home/arcturus/Projects/sharewood/venv/lib/python3.7/site-packages/django/urls/base.py", line 90, in reverse
    return iri_to_uri(resolver._reverse_with_prefix(view, prefix, *args, **kwargs))
  File "/home/arcturus/Projects/sharewood/venv/lib/python3.7/site-packages/django/urls/resolvers.py", line 668, in _reverse_with_prefix
    raise NoReverseMatch(msg)
django.urls.exceptions.NoReverseMatch: Reverse for 'api-data' with no arguments not found. 1 pattern(s) tried: ['api/(?P<data>[^/]+)$']
[2019-07-08 12:16:31,911] WARNING : Not Found: /api/registration/
[2019-07-08 12:16:32,783] WARNING : Not Found: /api/registration/
[2019-07-08 12:16:33,808] WARNING : Not Found: /api/registration/
[2019-07-08 12:50:09,191] WARNING : Not Found: /favicon.ico
[2019-07-08 13:21:58,906] WARNING : Not Found: /favicon.ico
[2019-07-08 13:22:00,063] WARNING : Not Found: /favicon.ico
[2019-07-08 13:22:19,237] WARNING : Not Found: /favicon.ico
[2019-07-08 13:22:50,582] WARNING : Not Found: /favicon.ico
[2019-07-08 13:23:03,380] WARNING : Not Found: /favicon.ico
[2019-07-08 13:26:15,326] INFO    : /home/arcturus/Projects/sharewood/app/views_api.py changed, reloading.
[2019-07-08 13:26:24,441] WARNING : Not Found: /favicon.ico
[2019-07-08 13:26:24,464] ERROR   : Internal Server Error: /api/registration
Traceback (most recent call last):
  File "/home/arcturus/Projects/sharewood/venv/lib/python3.7/site-packages/django/core/handlers/exception.py", line 34, in inner
    response = get_response(request)
  File "/home/arcturus/Projects/sharewood/venv/lib/python3.7/site-packages/django/core/handlers/base.py", line 115, in _get_response
    response = self.process_exception_by_middleware(e, request)
  File "/home/arcturus/Projects/sharewood/venv/lib/python3.7/site-packages/django/core/handlers/base.py", line 113, in _get_response
    response = wrapped_callback(request, *callback_args, **callback_kwargs)
  File "/home/arcturus/Projects/sharewood/app/views.py", line 515, in api
    return getattr(app.views_api, data)(request)
  File "/home/arcturus/Projects/sharewood/app/views_api.py", line 38, in registration
    data = dict(collections.Counter(format_date(obj.date_joined) for obj in users))
  File "/usr/lib/python3.7/collections/__init__.py", line 566, in __init__
    self.update(*args, **kwds)
  File "/usr/lib/python3.7/collections/__init__.py", line 653, in update
    _count_elements(self, iterable)
  File "/home/arcturus/Projects/sharewood/app/views_api.py", line 38, in <genexpr>
    data = dict(collections.Counter(format_date(obj.date_joined) for obj in users))
  File "/home/arcturus/Projects/sharewood/app/views_api.py", line 8, in format_date
    month = int(sdate[1])
IndexError: list index out of range
[2019-07-08 13:26:25,479] WARNING : Not Found: /favicon.ico
[2019-07-08 13:26:25,497] ERROR   : Internal Server Error: /api/registration
Traceback (most recent call last):
  File "/home/arcturus/Projects/sharewood/venv/lib/python3.7/site-packages/django/core/handlers/exception.py", line 34, in inner
    response = get_response(request)
  File "/home/arcturus/Projects/sharewood/venv/lib/python3.7/site-packages/django/core/handlers/base.py", line 115, in _get_response
    response = self.process_exception_by_middleware(e, request)
  File "/home/arcturus/Projects/sharewood/venv/lib/python3.7/site-packages/django/core/handlers/base.py", line 113, in _get_response
    response = wrapped_callback(request, *callback_args, **callback_kwargs)
  File "/home/arcturus/Projects/sharewood/app/views.py", line 515, in api
    return getattr(app.views_api, data)(request)
  File "/home/arcturus/Projects/sharewood/app/views_api.py", line 38, in registration
    data = dict(collections.Counter(format_date(obj.date_joined) for obj in users))
  File "/usr/lib/python3.7/collections/__init__.py", line 566, in __init__
    self.update(*args, **kwds)
  File "/usr/lib/python3.7/collections/__init__.py", line 653, in update
    _count_elements(self, iterable)
  File "/home/arcturus/Projects/sharewood/app/views_api.py", line 38, in <genexpr>
    data = dict(collections.Counter(format_date(obj.date_joined) for obj in users))
  File "/home/arcturus/Projects/sharewood/app/views_api.py", line 8, in format_date
    month = int(sdate[1])
IndexError: list index out of range
[2019-07-08 13:26:26,203] ERROR   : Internal Server Error: /api/registration
Traceback (most recent call last):
  File "/home/arcturus/Projects/sharewood/venv/lib/python3.7/site-packages/django/core/handlers/exception.py", line 34, in inner
    response = get_response(request)
  File "/home/arcturus/Projects/sharewood/venv/lib/python3.7/site-packages/django/core/handlers/base.py", line 115, in _get_response
    response = self.process_exception_by_middleware(e, request)
  File "/home/arcturus/Projects/sharewood/venv/lib/python3.7/site-packages/django/core/handlers/base.py", line 113, in _get_response
    response = wrapped_callback(request, *callback_args, **callback_kwargs)
  File "/home/arcturus/Projects/sharewood/app/views.py", line 515, in api
    return getattr(app.views_api, data)(request)
  File "/home/arcturus/Projects/sharewood/app/views_api.py", line 38, in registration
    data = dict(collections.Counter(format_date(obj.date_joined) for obj in users))
  File "/usr/lib/python3.7/collections/__init__.py", line 566, in __init__
    self.update(*args, **kwds)
  File "/usr/lib/python3.7/collections/__init__.py", line 653, in update
    _count_elements(self, iterable)
  File "/home/arcturus/Projects/sharewood/app/views_api.py", line 38, in <genexpr>
    data = dict(collections.Counter(format_date(obj.date_joined) for obj in users))
  File "/home/arcturus/Projects/sharewood/app/views_api.py", line 8, in format_date
    month = int(sdate[1])
IndexError: list index out of range
[2019-07-08 13:26:34,809] INFO    : /home/arcturus/Projects/sharewood/app/views_api.py changed, reloading.
[2019-07-08 13:26:38,179] WARNING : Not Found: /favicon.ico
[2019-07-08 13:26:38,200] ERROR   : Internal Server Error: /api/registration
Traceback (most recent call last):
  File "/home/arcturus/Projects/sharewood/venv/lib/python3.7/site-packages/django/core/handlers/exception.py", line 34, in inner
    response = get_response(request)
  File "/home/arcturus/Projects/sharewood/venv/lib/python3.7/site-packages/django/core/handlers/base.py", line 115, in _get_response
    response = self.process_exception_by_middleware(e, request)
  File "/home/arcturus/Projects/sharewood/venv/lib/python3.7/site-packages/django/core/handlers/base.py", line 113, in _get_response
    response = wrapped_callback(request, *callback_args, **callback_kwargs)
  File "/home/arcturus/Projects/sharewood/app/views.py", line 515, in api
    return getattr(app.views_api, data)(request)
  File "/home/arcturus/Projects/sharewood/app/views_api.py", line 39, in registration
    data = dict(collections.Counter(format_date(obj.date_joined) for obj in users))
  File "/usr/lib/python3.7/collections/__init__.py", line 566, in __init__
    self.update(*args, **kwds)
  File "/usr/lib/python3.7/collections/__init__.py", line 653, in update
    _count_elements(self, iterable)
  File "/home/arcturus/Projects/sharewood/app/views_api.py", line 39, in <genexpr>
    data = dict(collections.Counter(format_date(obj.date_joined) for obj in users))
  File "/home/arcturus/Projects/sharewood/app/views_api.py", line 9, in format_date
    month = int(sdate[1])
IndexError: list index out of range
[2019-07-08 13:26:47,318] ERROR   : Internal Server Error: /api/registration
Traceback (most recent call last):
  File "/home/arcturus/Projects/sharewood/venv/lib/python3.7/site-packages/django/core/handlers/exception.py", line 34, in inner
    response = get_response(request)
  File "/home/arcturus/Projects/sharewood/venv/lib/python3.7/site-packages/django/core/handlers/base.py", line 115, in _get_response
    response = self.process_exception_by_middleware(e, request)
  File "/home/arcturus/Projects/sharewood/venv/lib/python3.7/site-packages/django/core/handlers/base.py", line 113, in _get_response
    response = wrapped_callback(request, *callback_args, **callback_kwargs)
  File "/home/arcturus/Projects/sharewood/app/views.py", line 515, in api
    return getattr(app.views_api, data)(request)
  File "/home/arcturus/Projects/sharewood/app/views_api.py", line 39, in registration
    return django.http.JsonResponse(data)
  File "/usr/lib/python3.7/collections/__init__.py", line 566, in __init__
    self.update(*args, **kwds)
  File "/usr/lib/python3.7/collections/__init__.py", line 653, in update
    _count_elements(self, iterable)
  File "/home/arcturus/Projects/sharewood/app/views_api.py", line 39, in <genexpr>
    return django.http.JsonResponse(data)
  File "/home/arcturus/Projects/sharewood/app/views_api.py", line 9, in format_date
    if month == 1:
IndexError: list index out of range
[2019-07-08 13:26:47,561] INFO    : /home/arcturus/Projects/sharewood/app/views_api.py changed, reloading.
[2019-07-08 13:26:48,867] WARNING : Not Found: /favicon.ico
[2019-07-08 13:27:09,611] INFO    : /home/arcturus/Projects/sharewood/app/views_api.py changed, reloading.
[2019-07-08 13:28:26,363] WARNING : Not Found: /favicon.ico
[2019-07-08 13:28:36,063] WARNING : Not Found: /favicon.ico
[2019-07-08 13:29:45,819] WARNING : Not Found: /favicon.ico
[2019-07-08 13:30:23,812] WARNING : Not Found: /favicon.ico
[2019-07-08 13:31:48,343] WARNING : Not Found: /favicon.ico
[2019-07-08 13:31:49,434] WARNING : Not Found: /favicon.ico
[2019-07-08 13:32:47,306] WARNING : Not Found: /favicon.ico
[2019-07-08 13:32:48,077] WARNING : Not Found: /favicon.ico
[2019-07-08 13:34:09,941] WARNING : Not Found: /api/registrations
[2019-07-08 13:34:12,655] WARNING : Not Found: /api/registrations
[2019-07-08 13:35:05,460] INFO    : /home/arcturus/Projects/sharewood/app/views_api.py changed, reloading.
[2019-07-08 13:48:32,004] INFO    : /home/arcturus/Projects/sharewood/app/views_api.py changed, reloading.
[2019-07-08 14:25:27,205] WARNING : Not Found: /favicon.ico
[2019-07-08 14:27:13,373] WARNING : Not Found: /favicon.ico
[2019-07-08 15:34:27,276] INFO    : /home/arcturus/Projects/sharewood/app/views_api.py changed, reloading.
[2019-07-08 15:34:30,976] WARNING : Not Found: /api
[2019-07-08 15:34:55,041] ERROR   : Internal Server Error: /api/format_date
Traceback (most recent call last):
  File "/home/arcturus/Projects/sharewood/venv/lib/python3.7/site-packages/django/core/handlers/exception.py", line 34, in inner
    response = get_response(request)
  File "/home/arcturus/Projects/sharewood/venv/lib/python3.7/site-packages/django/core/handlers/base.py", line 115, in _get_response
    response = self.process_exception_by_middleware(e, request)
  File "/home/arcturus/Projects/sharewood/venv/lib/python3.7/site-packages/django/core/handlers/base.py", line 113, in _get_response
    response = wrapped_callback(request, *callback_args, **callback_kwargs)
  File "/home/arcturus/Projects/sharewood/app/views.py", line 515, in api
    return getattr(app.views_api, data)(request)
  File "/home/arcturus/Projects/sharewood/app/views_api.py", line 14, in format_date
    month = int(sdate[1])
IndexError: list index out of range
[2019-07-08 15:45:39,767] INFO    : /home/arcturus/Projects/sharewood/app/views.py changed, reloading.
[2019-07-08 15:47:17,539] INFO    : /home/arcturus/Projects/sharewood/app/views_api.py changed, reloading.
[2019-07-08 15:53:44,213] WARNING : Not Found: /api/format_date
[2019-07-08 15:53:51,620] ERROR   : Internal Server Error: /api/registrations
Traceback (most recent call last):
  File "/home/arcturus/Projects/sharewood/venv/lib/python3.7/site-packages/django/core/handlers/exception.py", line 34, in inner
    response = get_response(request)
  File "/home/arcturus/Projects/sharewood/venv/lib/python3.7/site-packages/django/core/handlers/base.py", line 115, in _get_response
    response = self.process_exception_by_middleware(e, request)
  File "/home/arcturus/Projects/sharewood/venv/lib/python3.7/site-packages/django/core/handlers/base.py", line 113, in _get_response
    response = wrapped_callback(request, *callback_args, **callback_kwargs)
  File "/home/arcturus/Projects/sharewood/app/views.py", line 515, in api
    return getattr(app.views_api, data)(request)
AttributeError: module 'app.views_api' has no attribute 'registrations'
[2019-07-08 15:53:58,581] WARNING : Not Found: /api/registration
[2019-07-08 15:54:04,559] ERROR   : Internal Server Error: /api/registrations
Traceback (most recent call last):
  File "/home/arcturus/Projects/sharewood/venv/lib/python3.7/site-packages/django/core/handlers/exception.py", line 34, in inner
    response = get_response(request)
  File "/home/arcturus/Projects/sharewood/venv/lib/python3.7/site-packages/django/core/handlers/base.py", line 115, in _get_response
    response = self.process_exception_by_middleware(e, request)
  File "/home/arcturus/Projects/sharewood/venv/lib/python3.7/site-packages/django/core/handlers/base.py", line 113, in _get_response
    response = wrapped_callback(request, *callback_args, **callback_kwargs)
  File "/home/arcturus/Projects/sharewood/app/views.py", line 515, in api
    return getattr(app.views_api, data)(request)
AttributeError: module 'app.views_api' has no attribute 'registrations'
[2019-07-08 15:54:14,102] INFO    : /home/arcturus/Projects/sharewood/app/views.py changed, reloading.
[2019-07-08 15:54:15,048] WARNING : Not Found: /api/registrations
[2019-07-08 16:01:12,358] INFO    : /home/arcturus/Projects/sharewood/app/views_api.py changed, reloading.
[2019-07-08 16:03:42,449] INFO    : /home/arcturus/Projects/sharewood/app/views_api.py changed, reloading.
[2019-07-08 16:05:07,095] INFO    : /home/arcturus/Projects/sharewood/app/views_api.py changed, reloading.
[2019-07-08 16:17:25,984] INFO    : /home/arcturus/Projects/sharewood/app/views_api.py changed, reloading.
[2019-07-08 16:27:50,416] ERROR   : Internal Server Error: /api/activity
Traceback (most recent call last):
  File "/home/arcturus/Projects/sharewood/venv/lib/python3.7/site-packages/django/core/handlers/exception.py", line 34, in inner
    response = get_response(request)
  File "/home/arcturus/Projects/sharewood/venv/lib/python3.7/site-packages/django/core/handlers/base.py", line 115, in _get_response
    response = self.process_exception_by_middleware(e, request)
  File "/home/arcturus/Projects/sharewood/venv/lib/python3.7/site-packages/django/core/handlers/base.py", line 113, in _get_response
    response = wrapped_callback(request, *callback_args, **callback_kwargs)
  File "/home/arcturus/Projects/sharewood/app/views.py", line 515, in api
    return getattr(app.views_api, data)(request)
  File "/home/arcturus/Projects/sharewood/app/views_api.py", line 22, in activity
    if (datetime.date.today() - datetime.timedelta(weeks=1)) < user.last_login:
TypeError: can't compare datetime.datetime to datetime.date
[2019-07-08 16:29:11,650] INFO    : /home/arcturus/Projects/sharewood/app/models.py changed, reloading.
[2019-07-08 16:29:39,974] INFO    : /home/arcturus/Projects/sharewood/app/views_api.py changed, reloading.
[2019-07-08 16:29:42,384] ERROR   : Internal Server Error: /api/activity
Traceback (most recent call last):
  File "/home/arcturus/Projects/sharewood/venv/lib/python3.7/site-packages/django/core/handlers/exception.py", line 34, in inner
    response = get_response(request)
  File "/home/arcturus/Projects/sharewood/venv/lib/python3.7/site-packages/django/core/handlers/base.py", line 115, in _get_response
    response = self.process_exception_by_middleware(e, request)
  File "/home/arcturus/Projects/sharewood/venv/lib/python3.7/site-packages/django/core/handlers/base.py", line 113, in _get_response
    response = wrapped_callback(request, *callback_args, **callback_kwargs)
  File "/home/arcturus/Projects/sharewood/app/views.py", line 515, in api
    return getattr(app.views_api, data)(request)
  File "/home/arcturus/Projects/sharewood/app/views_api.py", line 22, in activity
    if (datetime.date.today() - datetime.timedelta(weeks=1)) < user.last_login.date():
AttributeError: 'NoneType' object has no attribute 'date'
[2019-07-08 16:30:23,988] ERROR   : Internal Server Error: /api/activity
Traceback (most recent call last):
  File "/home/arcturus/Projects/sharewood/venv/lib/python3.7/site-packages/django/core/handlers/exception.py", line 34, in inner
    response = get_response(request)
  File "/home/arcturus/Projects/sharewood/venv/lib/python3.7/site-packages/django/core/handlers/base.py", line 115, in _get_response
    response = self.process_exception_by_middleware(e, request)
  File "/home/arcturus/Projects/sharewood/venv/lib/python3.7/site-packages/django/core/handlers/base.py", line 113, in _get_response
    response = wrapped_callback(request, *callback_args, **callback_kwargs)
  File "/home/arcturus/Projects/sharewood/app/views.py", line 515, in api
    return getattr(app.views_api, data)(request)
  File "/home/arcturus/Projects/sharewood/app/views_api.py", line 22, in activity
    if (datetime.date.today() - datetime.timedelta(weeks=1)) < user.last_login.date():
AttributeError: 'NoneType' object has no attribute 'date'
[2019-07-08 16:30:24,536] ERROR   : Internal Server Error: /api/activity
Traceback (most recent call last):
  File "/home/arcturus/Projects/sharewood/venv/lib/python3.7/site-packages/django/core/handlers/exception.py", line 34, in inner
    response = get_response(request)
  File "/home/arcturus/Projects/sharewood/venv/lib/python3.7/site-packages/django/core/handlers/base.py", line 115, in _get_response
    response = self.process_exception_by_middleware(e, request)
  File "/home/arcturus/Projects/sharewood/venv/lib/python3.7/site-packages/django/core/handlers/base.py", line 113, in _get_response
    response = wrapped_callback(request, *callback_args, **callback_kwargs)
  File "/home/arcturus/Projects/sharewood/app/views.py", line 515, in api
    return getattr(app.views_api, data)(request)
  File "/home/arcturus/Projects/sharewood/app/views_api.py", line 22, in activity
    if (datetime.date.today() - datetime.timedelta(weeks=1)) < user.last_login.date():
AttributeError: 'NoneType' object has no attribute 'date'
[2019-07-08 16:30:25,438] ERROR   : Internal Server Error: /api/activity
Traceback (most recent call last):
  File "/home/arcturus/Projects/sharewood/venv/lib/python3.7/site-packages/django/core/handlers/exception.py", line 34, in inner
    response = get_response(request)
  File "/home/arcturus/Projects/sharewood/venv/lib/python3.7/site-packages/django/core/handlers/base.py", line 115, in _get_response
    response = self.process_exception_by_middleware(e, request)
  File "/home/arcturus/Projects/sharewood/venv/lib/python3.7/site-packages/django/core/handlers/base.py", line 113, in _get_response
    response = wrapped_callback(request, *callback_args, **callback_kwargs)
  File "/home/arcturus/Projects/sharewood/app/views.py", line 515, in api
    return getattr(app.views_api, data)(request)
  File "/home/arcturus/Projects/sharewood/app/views_api.py", line 22, in activity
    if (datetime.date.today() - datetime.timedelta(weeks=1)) < user.last_login.date():
AttributeError: 'NoneType' object has no attribute 'date'
[2019-07-08 16:30:34,545] ERROR   : Internal Server Error: /api/activity
Traceback (most recent call last):
  File "/home/arcturus/Projects/sharewood/venv/lib/python3.7/site-packages/django/core/handlers/exception.py", line 34, in inner
    response = get_response(request)
  File "/home/arcturus/Projects/sharewood/venv/lib/python3.7/site-packages/django/core/handlers/base.py", line 115, in _get_response
    response = self.process_exception_by_middleware(e, request)
  File "/home/arcturus/Projects/sharewood/venv/lib/python3.7/site-packages/django/core/handlers/base.py", line 113, in _get_response
    response = wrapped_callback(request, *callback_args, **callback_kwargs)
  File "/home/arcturus/Projects/sharewood/app/views.py", line 515, in api
    return getattr(app.views_api, data)(request)
  File "/home/arcturus/Projects/sharewood/app/views_api.py", line 22, in activity
    if (datetime.date.today() - datetime.timedelta(weeks=1)) < user.last_login:
AttributeError: 'NoneType' object has no attribute 'date'
[2019-07-08 16:30:34,599] INFO    : /home/arcturus/Projects/sharewood/app/views_api.py changed, reloading.
[2019-07-08 16:31:23,780] INFO    : /home/arcturus/Projects/sharewood/app/models.py changed, reloading.
[2019-07-08 16:31:35,256] INFO    : /home/arcturus/Projects/sharewood/app/views_api.py changed, reloading.
[2019-07-08 16:31:38,004] ERROR   : Internal Server Error: /api/activity
Traceback (most recent call last):
  File "/home/arcturus/Projects/sharewood/venv/lib/python3.7/site-packages/django/core/handlers/exception.py", line 34, in inner
    response = get_response(request)
  File "/home/arcturus/Projects/sharewood/venv/lib/python3.7/site-packages/django/core/handlers/base.py", line 115, in _get_response
    response = self.process_exception_by_middleware(e, request)
  File "/home/arcturus/Projects/sharewood/venv/lib/python3.7/site-packages/django/core/handlers/base.py", line 113, in _get_response
    response = wrapped_callback(request, *callback_args, **callback_kwargs)
  File "/home/arcturus/Projects/sharewood/app/views.py", line 515, in api
    return getattr(app.views_api, data)(request)
  File "/home/arcturus/Projects/sharewood/app/views_api.py", line 23, in activity
    if (datetime.date.today() - datetime.timedelta(weeks=1)) < user.last_login:
TypeError: can't compare datetime.datetime to datetime.date
[2019-07-08 16:31:49,321] ERROR   : Internal Server Error: /api/activity
Traceback (most recent call last):
  File "/home/arcturus/Projects/sharewood/venv/lib/python3.7/site-packages/django/core/handlers/exception.py", line 34, in inner
    response = get_response(request)
  File "/home/arcturus/Projects/sharewood/venv/lib/python3.7/site-packages/django/core/handlers/base.py", line 115, in _get_response
    response = self.process_exception_by_middleware(e, request)
  File "/home/arcturus/Projects/sharewood/venv/lib/python3.7/site-packages/django/core/handlers/base.py", line 113, in _get_response
    response = wrapped_callback(request, *callback_args, **callback_kwargs)
  File "/home/arcturus/Projects/sharewood/app/views.py", line 515, in api
    return getattr(app.views_api, data)(request)
  File "/home/arcturus/Projects/sharewood/app/views_api.py", line 23, in activity
    if (datetime.date.today() - datetime.timedelta(weeks=1)) < user.last_login:
TypeError: can't compare datetime.datetime to datetime.date
[2019-07-08 16:31:49,769] INFO    : /home/arcturus/Projects/sharewood/app/views_api.py changed, reloading.
[2019-07-08 16:31:59,007] ERROR   : Internal Server Error: /api/activity
Traceback (most recent call last):
  File "/home/arcturus/Projects/sharewood/venv/lib/python3.7/site-packages/django/core/handlers/exception.py", line 34, in inner
    response = get_response(request)
  File "/home/arcturus/Projects/sharewood/venv/lib/python3.7/site-packages/django/core/handlers/base.py", line 115, in _get_response
    response = self.process_exception_by_middleware(e, request)
  File "/home/arcturus/Projects/sharewood/venv/lib/python3.7/site-packages/django/core/handlers/base.py", line 113, in _get_response
    response = wrapped_callback(request, *callback_args, **callback_kwargs)
  File "/home/arcturus/Projects/sharewood/app/views.py", line 515, in api
    return getattr(app.views_api, data)(request)
  File "/home/arcturus/Projects/sharewood/app/views_api.py", line 23, in activity
    if (datetime.date.today() - datetime.timedelta(weeks=1)) < user.last_login:
TypeError: can't compare datetime.datetime to datetime.date
[2019-07-08 16:32:16,977] INFO    : /home/arcturus/Projects/sharewood/app/views_api.py changed, reloading.
[2019-07-08 16:32:18,172] ERROR   : Internal Server Error: /api/activity
Traceback (most recent call last):
  File "/home/arcturus/Projects/sharewood/venv/lib/python3.7/site-packages/django/core/handlers/exception.py", line 34, in inner
    response = get_response(request)
  File "/home/arcturus/Projects/sharewood/venv/lib/python3.7/site-packages/django/core/handlers/base.py", line 115, in _get_response
    response = self.process_exception_by_middleware(e, request)
  File "/home/arcturus/Projects/sharewood/venv/lib/python3.7/site-packages/django/core/handlers/base.py", line 113, in _get_response
    response = wrapped_callback(request, *callback_args, **callback_kwargs)
  File "/home/arcturus/Projects/sharewood/app/views.py", line 515, in api
    return getattr(app.views_api, data)(request)
  File "/home/arcturus/Projects/sharewood/app/views_api.py", line 22, in activity
    if (datetime.date.today() - datetime.timedelta(weeks=1)) < user.last_login.date():
AttributeError: 'NoneType' object has no attribute 'date'
[2019-07-08 16:32:18,419] ERROR   : Internal Server Error: /api/activity
Traceback (most recent call last):
  File "/home/arcturus/Projects/sharewood/venv/lib/python3.7/site-packages/django/core/handlers/exception.py", line 34, in inner
    response = get_response(request)
  File "/home/arcturus/Projects/sharewood/venv/lib/python3.7/site-packages/django/core/handlers/base.py", line 115, in _get_response
    response = self.process_exception_by_middleware(e, request)
  File "/home/arcturus/Projects/sharewood/venv/lib/python3.7/site-packages/django/core/handlers/base.py", line 113, in _get_response
    response = wrapped_callback(request, *callback_args, **callback_kwargs)
  File "/home/arcturus/Projects/sharewood/app/views.py", line 515, in api
    return getattr(app.views_api, data)(request)
  File "/home/arcturus/Projects/sharewood/app/views_api.py", line 22, in activity
    if (datetime.date.today() - datetime.timedelta(weeks=1)) < user.last_login.date():
AttributeError: 'NoneType' object has no attribute 'date'
[2019-07-08 16:32:18,451] ERROR   : Internal Server Error: /api/activity
Traceback (most recent call last):
  File "/home/arcturus/Projects/sharewood/venv/lib/python3.7/site-packages/django/core/handlers/exception.py", line 34, in inner
    response = get_response(request)
  File "/home/arcturus/Projects/sharewood/venv/lib/python3.7/site-packages/django/core/handlers/base.py", line 115, in _get_response
    response = self.process_exception_by_middleware(e, request)
  File "/home/arcturus/Projects/sharewood/venv/lib/python3.7/site-packages/django/core/handlers/base.py", line 113, in _get_response
    response = wrapped_callback(request, *callback_args, **callback_kwargs)
  File "/home/arcturus/Projects/sharewood/app/views.py", line 515, in api
    return getattr(app.views_api, data)(request)
  File "/home/arcturus/Projects/sharewood/app/views_api.py", line 22, in activity
    if (datetime.date.today() - datetime.timedelta(weeks=1)) < user.last_login.date():
AttributeError: 'NoneType' object has no attribute 'date'
[2019-07-08 16:32:18,521] ERROR   : Internal Server Error: /api/activity
Traceback (most recent call last):
  File "/home/arcturus/Projects/sharewood/venv/lib/python3.7/site-packages/django/core/handlers/exception.py", line 34, in inner
    response = get_response(request)
  File "/home/arcturus/Projects/sharewood/venv/lib/python3.7/site-packages/django/core/handlers/base.py", line 115, in _get_response
    response = self.process_exception_by_middleware(e, request)
  File "/home/arcturus/Projects/sharewood/venv/lib/python3.7/site-packages/django/core/handlers/base.py", line 113, in _get_response
    response = wrapped_callback(request, *callback_args, **callback_kwargs)
  File "/home/arcturus/Projects/sharewood/app/views.py", line 515, in api
    return getattr(app.views_api, data)(request)
  File "/home/arcturus/Projects/sharewood/app/views_api.py", line 22, in activity
    if (datetime.date.today() - datetime.timedelta(weeks=1)) < user.last_login.date():
AttributeError: 'NoneType' object has no attribute 'date'
[2019-07-08 16:32:18,577] ERROR   : Internal Server Error: /api/activity
Traceback (most recent call last):
  File "/home/arcturus/Projects/sharewood/venv/lib/python3.7/site-packages/django/core/handlers/exception.py", line 34, in inner
    response = get_response(request)
  File "/home/arcturus/Projects/sharewood/venv/lib/python3.7/site-packages/django/core/handlers/base.py", line 115, in _get_response
    response = self.process_exception_by_middleware(e, request)
  File "/home/arcturus/Projects/sharewood/venv/lib/python3.7/site-packages/django/core/handlers/base.py", line 113, in _get_response
    response = wrapped_callback(request, *callback_args, **callback_kwargs)
  File "/home/arcturus/Projects/sharewood/app/views.py", line 515, in api
    return getattr(app.views_api, data)(request)
  File "/home/arcturus/Projects/sharewood/app/views_api.py", line 22, in activity
    if (datetime.date.today() - datetime.timedelta(weeks=1)) < user.last_login.date():
AttributeError: 'NoneType' object has no attribute 'date'
[2019-07-08 16:32:19,076] ERROR   : Internal Server Error: /api/activity
Traceback (most recent call last):
  File "/home/arcturus/Projects/sharewood/venv/lib/python3.7/site-packages/django/core/handlers/exception.py", line 34, in inner
    response = get_response(request)
  File "/home/arcturus/Projects/sharewood/venv/lib/python3.7/site-packages/django/core/handlers/base.py", line 115, in _get_response
    response = self.process_exception_by_middleware(e, request)
  File "/home/arcturus/Projects/sharewood/venv/lib/python3.7/site-packages/django/core/handlers/base.py", line 113, in _get_response
    response = wrapped_callback(request, *callback_args, **callback_kwargs)
  File "/home/arcturus/Projects/sharewood/app/views.py", line 515, in api
    return getattr(app.views_api, data)(request)
  File "/home/arcturus/Projects/sharewood/app/views_api.py", line 22, in activity
    if (datetime.date.today() - datetime.timedelta(weeks=1)) < user.last_login.date():
AttributeError: 'NoneType' object has no attribute 'date'
[2019-07-08 16:32:19,472] ERROR   : Internal Server Error: /api/activity
Traceback (most recent call last):
  File "/home/arcturus/Projects/sharewood/venv/lib/python3.7/site-packages/django/core/handlers/exception.py", line 34, in inner
    response = get_response(request)
  File "/home/arcturus/Projects/sharewood/venv/lib/python3.7/site-packages/django/core/handlers/base.py", line 115, in _get_response
    response = self.process_exception_by_middleware(e, request)
  File "/home/arcturus/Projects/sharewood/venv/lib/python3.7/site-packages/django/core/handlers/base.py", line 113, in _get_response
    response = wrapped_callback(request, *callback_args, **callback_kwargs)
  File "/home/arcturus/Projects/sharewood/app/views.py", line 515, in api
    return getattr(app.views_api, data)(request)
  File "/home/arcturus/Projects/sharewood/app/views_api.py", line 22, in activity
    if (datetime.date.today() - datetime.timedelta(weeks=1)) < user.last_login.date():
AttributeError: 'NoneType' object has no attribute 'date'
[2019-07-08 16:32:19,736] ERROR   : Internal Server Error: /api/activity
Traceback (most recent call last):
  File "/home/arcturus/Projects/sharewood/venv/lib/python3.7/site-packages/django/core/handlers/exception.py", line 34, in inner
    response = get_response(request)
  File "/home/arcturus/Projects/sharewood/venv/lib/python3.7/site-packages/django/core/handlers/base.py", line 115, in _get_response
    response = self.process_exception_by_middleware(e, request)
  File "/home/arcturus/Projects/sharewood/venv/lib/python3.7/site-packages/django/core/handlers/base.py", line 113, in _get_response
    response = wrapped_callback(request, *callback_args, **callback_kwargs)
  File "/home/arcturus/Projects/sharewood/app/views.py", line 515, in api
    return getattr(app.views_api, data)(request)
  File "/home/arcturus/Projects/sharewood/app/views_api.py", line 22, in activity
    if (datetime.date.today() - datetime.timedelta(weeks=1)) < user.last_login.date():
AttributeError: 'NoneType' object has no attribute 'date'
[2019-07-08 16:32:19,945] ERROR   : Internal Server Error: /api/activity
Traceback (most recent call last):
  File "/home/arcturus/Projects/sharewood/venv/lib/python3.7/site-packages/django/core/handlers/exception.py", line 34, in inner
    response = get_response(request)
  File "/home/arcturus/Projects/sharewood/venv/lib/python3.7/site-packages/django/core/handlers/base.py", line 115, in _get_response
    response = self.process_exception_by_middleware(e, request)
  File "/home/arcturus/Projects/sharewood/venv/lib/python3.7/site-packages/django/core/handlers/base.py", line 113, in _get_response
    response = wrapped_callback(request, *callback_args, **callback_kwargs)
  File "/home/arcturus/Projects/sharewood/app/views.py", line 515, in api
    return getattr(app.views_api, data)(request)
  File "/home/arcturus/Projects/sharewood/app/views_api.py", line 22, in activity
    if (datetime.date.today() - datetime.timedelta(weeks=1)) < user.last_login.date():
AttributeError: 'NoneType' object has no attribute 'date'
[2019-07-08 16:32:20,148] ERROR   : Internal Server Error: /api/activity
Traceback (most recent call last):
  File "/home/arcturus/Projects/sharewood/venv/lib/python3.7/site-packages/django/core/handlers/exception.py", line 34, in inner
    response = get_response(request)
  File "/home/arcturus/Projects/sharewood/venv/lib/python3.7/site-packages/django/core/handlers/base.py", line 115, in _get_response
    response = self.process_exception_by_middleware(e, request)
  File "/home/arcturus/Projects/sharewood/venv/lib/python3.7/site-packages/django/core/handlers/base.py", line 113, in _get_response
    response = wrapped_callback(request, *callback_args, **callback_kwargs)
  File "/home/arcturus/Projects/sharewood/app/views.py", line 515, in api
    return getattr(app.views_api, data)(request)
  File "/home/arcturus/Projects/sharewood/app/views_api.py", line 22, in activity
    if (datetime.date.today() - datetime.timedelta(weeks=1)) < user.last_login.date():
AttributeError: 'NoneType' object has no attribute 'date'
[2019-07-08 16:32:20,339] ERROR   : Internal Server Error: /api/activity
Traceback (most recent call last):
  File "/home/arcturus/Projects/sharewood/venv/lib/python3.7/site-packages/django/core/handlers/exception.py", line 34, in inner
    response = get_response(request)
  File "/home/arcturus/Projects/sharewood/venv/lib/python3.7/site-packages/django/core/handlers/base.py", line 115, in _get_response
    response = self.process_exception_by_middleware(e, request)
  File "/home/arcturus/Projects/sharewood/venv/lib/python3.7/site-packages/django/core/handlers/base.py", line 113, in _get_response
    response = wrapped_callback(request, *callback_args, **callback_kwargs)
  File "/home/arcturus/Projects/sharewood/app/views.py", line 515, in api
    return getattr(app.views_api, data)(request)
  File "/home/arcturus/Projects/sharewood/app/views_api.py", line 22, in activity
    if (datetime.date.today() - datetime.timedelta(weeks=1)) < user.last_login.date():
AttributeError: 'NoneType' object has no attribute 'date'
[2019-07-08 16:33:36,958] ERROR   : Internal Server Error: /api/activity
Traceback (most recent call last):
  File "/home/arcturus/Projects/sharewood/venv/lib/python3.7/site-packages/django/core/handlers/exception.py", line 34, in inner
    response = get_response(request)
  File "/home/arcturus/Projects/sharewood/venv/lib/python3.7/site-packages/django/core/handlers/base.py", line 115, in _get_response
    response = self.process_exception_by_middleware(e, request)
  File "/home/arcturus/Projects/sharewood/venv/lib/python3.7/site-packages/django/core/handlers/base.py", line 113, in _get_response
    response = wrapped_callback(request, *callback_args, **callback_kwargs)
  File "/home/arcturus/Projects/sharewood/app/views.py", line 515, in api
    return getattr(app.views_api, data)(request)
  File "/home/arcturus/Projects/sharewood/app/views_api.py", line 22, in activity
    if (datetime.date.today() - datetime.timedelta(weeks=1)) < user.last_login.date():
AttributeError: 'NoneType' object has no attribute 'date'
[2019-07-08 16:34:00,427] ERROR   : Internal Server Error: /api/activity
Traceback (most recent call last):
  File "/home/arcturus/Projects/sharewood/venv/lib/python3.7/site-packages/django/core/handlers/exception.py", line 34, in inner
    response = get_response(request)
  File "/home/arcturus/Projects/sharewood/venv/lib/python3.7/site-packages/django/core/handlers/base.py", line 115, in _get_response
    response = self.process_exception_by_middleware(e, request)
  File "/home/arcturus/Projects/sharewood/venv/lib/python3.7/site-packages/django/core/handlers/base.py", line 113, in _get_response
    response = wrapped_callback(request, *callback_args, **callback_kwargs)
  File "/home/arcturus/Projects/sharewood/app/views.py", line 515, in api
    return getattr(app.views_api, data)(request)
  File "/home/arcturus/Projects/sharewood/app/views_api.py", line 22, in activity
    print(user.last_login.date())
AttributeError: 'NoneType' object has no attribute 'date'
[2019-07-08 16:34:00,439] INFO    : /home/arcturus/Projects/sharewood/app/views_api.py changed, reloading.
[2019-07-08 16:34:08,871] ERROR   : Internal Server Error: /api/activity
Traceback (most recent call last):
  File "/home/arcturus/Projects/sharewood/venv/lib/python3.7/site-packages/django/core/handlers/exception.py", line 34, in inner
    response = get_response(request)
  File "/home/arcturus/Projects/sharewood/venv/lib/python3.7/site-packages/django/core/handlers/base.py", line 115, in _get_response
    response = self.process_exception_by_middleware(e, request)
  File "/home/arcturus/Projects/sharewood/venv/lib/python3.7/site-packages/django/core/handlers/base.py", line 113, in _get_response
    response = wrapped_callback(request, *callback_args, **callback_kwargs)
  File "/home/arcturus/Projects/sharewood/app/views.py", line 515, in api
    return getattr(app.views_api, data)(request)
  File "/home/arcturus/Projects/sharewood/app/views_api.py", line 22, in activity
    print(user.last_login.date())
AttributeError: 'NoneType' object has no attribute 'date'
[2019-07-08 16:34:57,170] ERROR   : Internal Server Error: /api/activity
Traceback (most recent call last):
  File "/home/arcturus/Projects/sharewood/venv/lib/python3.7/site-packages/django/core/handlers/exception.py", line 34, in inner
    response = get_response(request)
  File "/home/arcturus/Projects/sharewood/venv/lib/python3.7/site-packages/django/core/handlers/base.py", line 115, in _get_response
    response = self.process_exception_by_middleware(e, request)
  File "/home/arcturus/Projects/sharewood/venv/lib/python3.7/site-packages/django/core/handlers/base.py", line 113, in _get_response
    response = wrapped_callback(request, *callback_args, **callback_kwargs)
  File "/home/arcturus/Projects/sharewood/app/views.py", line 515, in api
    return getattr(app.views_api, data)(request)
  File "/home/arcturus/Projects/sharewood/app/views_api.py", line 22, in activity
    if (datetime.date.today() - datetime.timedelta(weeks=1)) < user.last_login.date():
AttributeError: 'NoneType' object has no attribute 'date'
[2019-07-08 16:35:14,393] ERROR   : Internal Server Error: /api/activity
Traceback (most recent call last):
  File "/home/arcturus/Projects/sharewood/venv/lib/python3.7/site-packages/django/core/handlers/exception.py", line 34, in inner
    response = get_response(request)
  File "/home/arcturus/Projects/sharewood/venv/lib/python3.7/site-packages/django/core/handlers/base.py", line 115, in _get_response
    response = self.process_exception_by_middleware(e, request)
  File "/home/arcturus/Projects/sharewood/venv/lib/python3.7/site-packages/django/core/handlers/base.py", line 113, in _get_response
    response = wrapped_callback(request, *callback_args, **callback_kwargs)
  File "/home/arcturus/Projects/sharewood/app/views.py", line 515, in api
    return getattr(app.views_api, data)(request)
  File "/home/arcturus/Projects/sharewood/app/views_api.py", line 22, in activity
    if (datetime.date.today() - datetime.timedelta(weeks=1)) < user.last_login.date():
AttributeError: 'NoneType' object has no attribute 'date'
[2019-07-08 16:35:28,105] ERROR   : Internal Server Error: /api/activity
Traceback (most recent call last):
  File "/home/arcturus/Projects/sharewood/venv/lib/python3.7/site-packages/django/core/handlers/exception.py", line 34, in inner
    response = get_response(request)
  File "/home/arcturus/Projects/sharewood/venv/lib/python3.7/site-packages/django/core/handlers/base.py", line 115, in _get_response
    response = self.process_exception_by_middleware(e, request)
  File "/home/arcturus/Projects/sharewood/venv/lib/python3.7/site-packages/django/core/handlers/base.py", line 113, in _get_response
    response = wrapped_callback(request, *callback_args, **callback_kwargs)
  File "/home/arcturus/Projects/sharewood/app/views.py", line 515, in api
    return getattr(app.views_api, data)(request)
  File "/home/arcturus/Projects/sharewood/app/views_api.py", line 22, in activity
    if (datetime.date.today() - datetime.timedelta(weeks=1)) < user.last_login.date():
AttributeError: 'NoneType' object has no attribute 'date'
[2019-07-08 16:35:28,870] ERROR   : Internal Server Error: /api/activity
Traceback (most recent call last):
  File "/home/arcturus/Projects/sharewood/venv/lib/python3.7/site-packages/django/core/handlers/exception.py", line 34, in inner
    response = get_response(request)
  File "/home/arcturus/Projects/sharewood/venv/lib/python3.7/site-packages/django/core/handlers/base.py", line 115, in _get_response
    response = self.process_exception_by_middleware(e, request)
  File "/home/arcturus/Projects/sharewood/venv/lib/python3.7/site-packages/django/core/handlers/base.py", line 113, in _get_response
    response = wrapped_callback(request, *callback_args, **callback_kwargs)
  File "/home/arcturus/Projects/sharewood/app/views.py", line 515, in api
    return getattr(app.views_api, data)(request)
  File "/home/arcturus/Projects/sharewood/app/views_api.py", line 22, in activity
    if (datetime.date.today() - datetime.timedelta(weeks=1)) < user.last_login.date():
AttributeError: 'NoneType' object has no attribute 'date'
[2019-07-08 16:35:29,326] ERROR   : Internal Server Error: /api/activity
Traceback (most recent call last):
  File "/home/arcturus/Projects/sharewood/venv/lib/python3.7/site-packages/django/core/handlers/exception.py", line 34, in inner
    response = get_response(request)
  File "/home/arcturus/Projects/sharewood/venv/lib/python3.7/site-packages/django/core/handlers/base.py", line 115, in _get_response
    response = self.process_exception_by_middleware(e, request)
  File "/home/arcturus/Projects/sharewood/venv/lib/python3.7/site-packages/django/core/handlers/base.py", line 113, in _get_response
    response = wrapped_callback(request, *callback_args, **callback_kwargs)
  File "/home/arcturus/Projects/sharewood/app/views.py", line 515, in api
    return getattr(app.views_api, data)(request)
  File "/home/arcturus/Projects/sharewood/app/views_api.py", line 22, in activity
    if (datetime.date.today() - datetime.timedelta(weeks=1)) < user.last_login.date():
AttributeError: 'NoneType' object has no attribute 'date'
[2019-07-08 16:35:47,436] ERROR   : Internal Server Error: /api/activity
Traceback (most recent call last):
  File "/home/arcturus/Projects/sharewood/venv/lib/python3.7/site-packages/django/core/handlers/exception.py", line 34, in inner
    response = get_response(request)
  File "/home/arcturus/Projects/sharewood/venv/lib/python3.7/site-packages/django/core/handlers/base.py", line 115, in _get_response
    response = self.process_exception_by_middleware(e, request)
  File "/home/arcturus/Projects/sharewood/venv/lib/python3.7/site-packages/django/core/handlers/base.py", line 113, in _get_response
    response = wrapped_callback(request, *callback_args, **callback_kwargs)
  File "/home/arcturus/Projects/sharewood/app/views.py", line 515, in api
    return getattr(app.views_api, data)(request)
  File "/home/arcturus/Projects/sharewood/app/views_api.py", line 22, in activity
    if (datetime.date.today() - datetime.timedelta(weeks=1)) < user.last_login.date():
AttributeError: 'NoneType' object has no attribute 'date'
[2019-07-08 16:35:48,197] ERROR   : Internal Server Error: /api/activity
Traceback (most recent call last):
  File "/home/arcturus/Projects/sharewood/venv/lib/python3.7/site-packages/django/core/handlers/exception.py", line 34, in inner
    response = get_response(request)
  File "/home/arcturus/Projects/sharewood/venv/lib/python3.7/site-packages/django/core/handlers/base.py", line 115, in _get_response
    response = self.process_exception_by_middleware(e, request)
  File "/home/arcturus/Projects/sharewood/venv/lib/python3.7/site-packages/django/core/handlers/base.py", line 113, in _get_response
    response = wrapped_callback(request, *callback_args, **callback_kwargs)
  File "/home/arcturus/Projects/sharewood/app/views.py", line 515, in api
    return getattr(app.views_api, data)(request)
  File "/home/arcturus/Projects/sharewood/app/views_api.py", line 22, in activity
    if (datetime.date.today() - datetime.timedelta(weeks=1)) < user.last_login.date():
AttributeError: 'NoneType' object has no attribute 'date'
[2019-07-08 16:35:48,541] ERROR   : Internal Server Error: /api/activity
Traceback (most recent call last):
  File "/home/arcturus/Projects/sharewood/venv/lib/python3.7/site-packages/django/core/handlers/exception.py", line 34, in inner
    response = get_response(request)
  File "/home/arcturus/Projects/sharewood/venv/lib/python3.7/site-packages/django/core/handlers/base.py", line 115, in _get_response
    response = self.process_exception_by_middleware(e, request)
  File "/home/arcturus/Projects/sharewood/venv/lib/python3.7/site-packages/django/core/handlers/base.py", line 113, in _get_response
    response = wrapped_callback(request, *callback_args, **callback_kwargs)
  File "/home/arcturus/Projects/sharewood/app/views.py", line 515, in api
    return getattr(app.views_api, data)(request)
  File "/home/arcturus/Projects/sharewood/app/views_api.py", line 22, in activity
    if (datetime.date.today() - datetime.timedelta(weeks=1)) < user.last_login.date():
AttributeError: 'NoneType' object has no attribute 'date'
[2019-07-08 16:35:48,840] ERROR   : Internal Server Error: /api/activity
Traceback (most recent call last):
  File "/home/arcturus/Projects/sharewood/venv/lib/python3.7/site-packages/django/core/handlers/exception.py", line 34, in inner
    response = get_response(request)
  File "/home/arcturus/Projects/sharewood/venv/lib/python3.7/site-packages/django/core/handlers/base.py", line 115, in _get_response
    response = self.process_exception_by_middleware(e, request)
  File "/home/arcturus/Projects/sharewood/venv/lib/python3.7/site-packages/django/core/handlers/base.py", line 113, in _get_response
    response = wrapped_callback(request, *callback_args, **callback_kwargs)
  File "/home/arcturus/Projects/sharewood/app/views.py", line 515, in api
    return getattr(app.views_api, data)(request)
  File "/home/arcturus/Projects/sharewood/app/views_api.py", line 22, in activity
    if (datetime.date.today() - datetime.timedelta(weeks=1)) < user.last_login.date():
AttributeError: 'NoneType' object has no attribute 'date'
[2019-07-08 16:35:49,056] ERROR   : Internal Server Error: /api/activity
Traceback (most recent call last):
  File "/home/arcturus/Projects/sharewood/venv/lib/python3.7/site-packages/django/core/handlers/exception.py", line 34, in inner
    response = get_response(request)
  File "/home/arcturus/Projects/sharewood/venv/lib/python3.7/site-packages/django/core/handlers/base.py", line 115, in _get_response
    response = self.process_exception_by_middleware(e, request)
  File "/home/arcturus/Projects/sharewood/venv/lib/python3.7/site-packages/django/core/handlers/base.py", line 113, in _get_response
    response = wrapped_callback(request, *callback_args, **callback_kwargs)
  File "/home/arcturus/Projects/sharewood/app/views.py", line 515, in api
    return getattr(app.views_api, data)(request)
  File "/home/arcturus/Projects/sharewood/app/views_api.py", line 22, in activity
    if (datetime.date.today() - datetime.timedelta(weeks=1)) < user.last_login.date():
AttributeError: 'NoneType' object has no attribute 'date'
[2019-07-08 16:37:40,538] ERROR   : Internal Server Error: /api/activity
Traceback (most recent call last):
  File "/home/arcturus/Projects/sharewood/venv/lib/python3.7/site-packages/django/core/handlers/exception.py", line 34, in inner
    response = get_response(request)
  File "/home/arcturus/Projects/sharewood/venv/lib/python3.7/site-packages/django/core/handlers/base.py", line 115, in _get_response
    response = self.process_exception_by_middleware(e, request)
  File "/home/arcturus/Projects/sharewood/venv/lib/python3.7/site-packages/django/core/handlers/base.py", line 113, in _get_response
    response = wrapped_callback(request, *callback_args, **callback_kwargs)
  File "/home/arcturus/Projects/sharewood/app/views.py", line 515, in api
    return getattr(app.views_api, data)(request)
  File "/home/arcturus/Projects/sharewood/app/views_api.py", line 22, in activity
    if (datetime.date.today() - datetime.timedelta(weeks=1)) < user.last_login.date():
AttributeError: 'NoneType' object has no attribute 'date'
[2019-07-08 16:37:41,167] ERROR   : Internal Server Error: /api/activity
Traceback (most recent call last):
  File "/home/arcturus/Projects/sharewood/venv/lib/python3.7/site-packages/django/core/handlers/exception.py", line 34, in inner
    response = get_response(request)
  File "/home/arcturus/Projects/sharewood/venv/lib/python3.7/site-packages/django/core/handlers/base.py", line 115, in _get_response
    response = self.process_exception_by_middleware(e, request)
  File "/home/arcturus/Projects/sharewood/venv/lib/python3.7/site-packages/django/core/handlers/base.py", line 113, in _get_response
    response = wrapped_callback(request, *callback_args, **callback_kwargs)
  File "/home/arcturus/Projects/sharewood/app/views.py", line 515, in api
    return getattr(app.views_api, data)(request)
  File "/home/arcturus/Projects/sharewood/app/views_api.py", line 22, in activity
    if (datetime.date.today() - datetime.timedelta(weeks=1)) < user.last_login.date():
AttributeError: 'NoneType' object has no attribute 'date'
[2019-07-08 16:37:41,419] ERROR   : Internal Server Error: /api/activity
Traceback (most recent call last):
  File "/home/arcturus/Projects/sharewood/venv/lib/python3.7/site-packages/django/core/handlers/exception.py", line 34, in inner
    response = get_response(request)
  File "/home/arcturus/Projects/sharewood/venv/lib/python3.7/site-packages/django/core/handlers/base.py", line 115, in _get_response
    response = self.process_exception_by_middleware(e, request)
  File "/home/arcturus/Projects/sharewood/venv/lib/python3.7/site-packages/django/core/handlers/base.py", line 113, in _get_response
    response = wrapped_callback(request, *callback_args, **callback_kwargs)
  File "/home/arcturus/Projects/sharewood/app/views.py", line 515, in api
    return getattr(app.views_api, data)(request)
  File "/home/arcturus/Projects/sharewood/app/views_api.py", line 22, in activity
    if (datetime.date.today() - datetime.timedelta(weeks=1)) < user.last_login.date():
AttributeError: 'NoneType' object has no attribute 'date'
[2019-07-08 16:37:41,452] ERROR   : Internal Server Error: /api/activity
Traceback (most recent call last):
  File "/home/arcturus/Projects/sharewood/venv/lib/python3.7/site-packages/django/core/handlers/exception.py", line 34, in inner
    response = get_response(request)
  File "/home/arcturus/Projects/sharewood/venv/lib/python3.7/site-packages/django/core/handlers/base.py", line 115, in _get_response
    response = self.process_exception_by_middleware(e, request)
  File "/home/arcturus/Projects/sharewood/venv/lib/python3.7/site-packages/django/core/handlers/base.py", line 113, in _get_response
    response = wrapped_callback(request, *callback_args, **callback_kwargs)
  File "/home/arcturus/Projects/sharewood/app/views.py", line 515, in api
    return getattr(app.views_api, data)(request)
  File "/home/arcturus/Projects/sharewood/app/views_api.py", line 22, in activity
    if (datetime.date.today() - datetime.timedelta(weeks=1)) < user.last_login.date():
AttributeError: 'NoneType' object has no attribute 'date'
[2019-07-08 16:37:41,509] ERROR   : Internal Server Error: /api/activity
Traceback (most recent call last):
  File "/home/arcturus/Projects/sharewood/venv/lib/python3.7/site-packages/django/core/handlers/exception.py", line 34, in inner
    response = get_response(request)
  File "/home/arcturus/Projects/sharewood/venv/lib/python3.7/site-packages/django/core/handlers/base.py", line 115, in _get_response
    response = self.process_exception_by_middleware(e, request)
  File "/home/arcturus/Projects/sharewood/venv/lib/python3.7/site-packages/django/core/handlers/base.py", line 113, in _get_response
    response = wrapped_callback(request, *callback_args, **callback_kwargs)
  File "/home/arcturus/Projects/sharewood/app/views.py", line 515, in api
    return getattr(app.views_api, data)(request)
  File "/home/arcturus/Projects/sharewood/app/views_api.py", line 22, in activity
    if (datetime.date.today() - datetime.timedelta(weeks=1)) < user.last_login.date():
AttributeError: 'NoneType' object has no attribute 'date'
[2019-07-08 16:37:41,546] ERROR   : Internal Server Error: /api/activity
Traceback (most recent call last):
  File "/home/arcturus/Projects/sharewood/venv/lib/python3.7/site-packages/django/core/handlers/exception.py", line 34, in inner
    response = get_response(request)
  File "/home/arcturus/Projects/sharewood/venv/lib/python3.7/site-packages/django/core/handlers/base.py", line 115, in _get_response
    response = self.process_exception_by_middleware(e, request)
  File "/home/arcturus/Projects/sharewood/venv/lib/python3.7/site-packages/django/core/handlers/base.py", line 113, in _get_response
    response = wrapped_callback(request, *callback_args, **callback_kwargs)
  File "/home/arcturus/Projects/sharewood/app/views.py", line 515, in api
    return getattr(app.views_api, data)(request)
  File "/home/arcturus/Projects/sharewood/app/views_api.py", line 22, in activity
    if (datetime.date.today() - datetime.timedelta(weeks=1)) < user.last_login.date():
AttributeError: 'NoneType' object has no attribute 'date'
[2019-07-08 16:37:41,630] ERROR   : Internal Server Error: /api/activity
Traceback (most recent call last):
  File "/home/arcturus/Projects/sharewood/venv/lib/python3.7/site-packages/django/core/handlers/exception.py", line 34, in inner
    response = get_response(request)
  File "/home/arcturus/Projects/sharewood/venv/lib/python3.7/site-packages/django/core/handlers/base.py", line 115, in _get_response
    response = self.process_exception_by_middleware(e, request)
  File "/home/arcturus/Projects/sharewood/venv/lib/python3.7/site-packages/django/core/handlers/base.py", line 113, in _get_response
    response = wrapped_callback(request, *callback_args, **callback_kwargs)
  File "/home/arcturus/Projects/sharewood/app/views.py", line 515, in api
    return getattr(app.views_api, data)(request)
  File "/home/arcturus/Projects/sharewood/app/views_api.py", line 22, in activity
    if (datetime.date.today() - datetime.timedelta(weeks=1)) < user.last_login.date():
AttributeError: 'NoneType' object has no attribute 'date'
[2019-07-08 16:37:41,686] ERROR   : Internal Server Error: /api/activity
Traceback (most recent call last):
  File "/home/arcturus/Projects/sharewood/venv/lib/python3.7/site-packages/django/core/handlers/exception.py", line 34, in inner
    response = get_response(request)
  File "/home/arcturus/Projects/sharewood/venv/lib/python3.7/site-packages/django/core/handlers/base.py", line 115, in _get_response
    response = self.process_exception_by_middleware(e, request)
  File "/home/arcturus/Projects/sharewood/venv/lib/python3.7/site-packages/django/core/handlers/base.py", line 113, in _get_response
    response = wrapped_callback(request, *callback_args, **callback_kwargs)
  File "/home/arcturus/Projects/sharewood/app/views.py", line 515, in api
    return getattr(app.views_api, data)(request)
  File "/home/arcturus/Projects/sharewood/app/views_api.py", line 22, in activity
    if (datetime.date.today() - datetime.timedelta(weeks=1)) < user.last_login.date():
AttributeError: 'NoneType' object has no attribute 'date'
[2019-07-08 16:37:41,716] ERROR   : Internal Server Error: /api/activity
Traceback (most recent call last):
  File "/home/arcturus/Projects/sharewood/venv/lib/python3.7/site-packages/django/core/handlers/exception.py", line 34, in inner
    response = get_response(request)
  File "/home/arcturus/Projects/sharewood/venv/lib/python3.7/site-packages/django/core/handlers/base.py", line 115, in _get_response
    response = self.process_exception_by_middleware(e, request)
  File "/home/arcturus/Projects/sharewood/venv/lib/python3.7/site-packages/django/core/handlers/base.py", line 113, in _get_response
    response = wrapped_callback(request, *callback_args, **callback_kwargs)
  File "/home/arcturus/Projects/sharewood/app/views.py", line 515, in api
    return getattr(app.views_api, data)(request)
  File "/home/arcturus/Projects/sharewood/app/views_api.py", line 22, in activity
    if (datetime.date.today() - datetime.timedelta(weeks=1)) < user.last_login.date():
AttributeError: 'NoneType' object has no attribute 'date'
[2019-07-08 16:37:41,748] ERROR   : Internal Server Error: /api/activity
Traceback (most recent call last):
  File "/home/arcturus/Projects/sharewood/venv/lib/python3.7/site-packages/django/core/handlers/exception.py", line 34, in inner
    response = get_response(request)
  File "/home/arcturus/Projects/sharewood/venv/lib/python3.7/site-packages/django/core/handlers/base.py", line 115, in _get_response
    response = self.process_exception_by_middleware(e, request)
  File "/home/arcturus/Projects/sharewood/venv/lib/python3.7/site-packages/django/core/handlers/base.py", line 113, in _get_response
    response = wrapped_callback(request, *callback_args, **callback_kwargs)
  File "/home/arcturus/Projects/sharewood/app/views.py", line 515, in api
    return getattr(app.views_api, data)(request)
  File "/home/arcturus/Projects/sharewood/app/views_api.py", line 22, in activity
    if (datetime.date.today() - datetime.timedelta(weeks=1)) < user.last_login.date():
AttributeError: 'NoneType' object has no attribute 'date'
[2019-07-08 16:44:12,335] WARNING : Not Found: /favicon.ico
[2019-07-08 17:02:06,972] WARNING : Not Found: /favicon.ico
[2019-07-08 17:03:29,273] WARNING : Not Found: /favicon.ico
[2019-07-08 17:07:17,447] WARNING : Not Found: /favicon.ico
[2019-07-08 17:07:33,262] WARNING : Not Found: /favicon.ico
[2019-07-08 17:24:47,274] WARNING : Not Found: /favicon.ico
[2019-07-08 17:27:29,483] INFO    : /home/arcturus/Projects/sharewood/app/views_api.py changed, reloading.
[2019-07-08 17:28:23,544] ERROR   : Internal Server Error: /api/activity
Traceback (most recent call last):
  File "/home/arcturus/Projects/sharewood/venv/lib/python3.7/site-packages/django/core/handlers/exception.py", line 34, in inner
    response = get_response(request)
  File "/home/arcturus/Projects/sharewood/venv/lib/python3.7/site-packages/django/core/handlers/base.py", line 115, in _get_response
    response = self.process_exception_by_middleware(e, request)
  File "/home/arcturus/Projects/sharewood/venv/lib/python3.7/site-packages/django/core/handlers/base.py", line 113, in _get_response
    response = wrapped_callback(request, *callback_args, **callback_kwargs)
  File "/home/arcturus/Projects/sharewood/app/views.py", line 546, in api
    return getattr(app.views_api, data)(request)
  File "/home/arcturus/Projects/sharewood/app/views_api.py", line 25, in activity
    data['last_month'] += 1
KeyError: 'last_month'
[2019-07-08 17:28:25,291] WARNING : Not Found: /favicon.ico
[2019-07-08 17:28:25,306] ERROR   : Internal Server Error: /api/activity
Traceback (most recent call last):
  File "/home/arcturus/Projects/sharewood/venv/lib/python3.7/site-packages/django/core/handlers/exception.py", line 34, in inner
    response = get_response(request)
  File "/home/arcturus/Projects/sharewood/venv/lib/python3.7/site-packages/django/core/handlers/base.py", line 115, in _get_response
    response = self.process_exception_by_middleware(e, request)
  File "/home/arcturus/Projects/sharewood/venv/lib/python3.7/site-packages/django/core/handlers/base.py", line 113, in _get_response
    response = wrapped_callback(request, *callback_args, **callback_kwargs)
  File "/home/arcturus/Projects/sharewood/app/views.py", line 546, in api
    return getattr(app.views_api, data)(request)
  File "/home/arcturus/Projects/sharewood/app/views_api.py", line 25, in activity
    data['last_month'] += 1
KeyError: 'last_month'
[2019-07-08 17:28:28,963] ERROR   : Internal Server Error: /api/activity
Traceback (most recent call last):
  File "/home/arcturus/Projects/sharewood/venv/lib/python3.7/site-packages/django/core/handlers/exception.py", line 34, in inner
    response = get_response(request)
  File "/home/arcturus/Projects/sharewood/venv/lib/python3.7/site-packages/django/core/handlers/base.py", line 115, in _get_response
    response = self.process_exception_by_middleware(e, request)
  File "/home/arcturus/Projects/sharewood/venv/lib/python3.7/site-packages/django/core/handlers/base.py", line 113, in _get_response
    response = wrapped_callback(request, *callback_args, **callback_kwargs)
  File "/home/arcturus/Projects/sharewood/app/views.py", line 546, in api
    return getattr(app.views_api, data)(request)
  File "/home/arcturus/Projects/sharewood/app/views_api.py", line 25, in activity
    data['last_month'] += 1
KeyError: 'last_month'
[2019-07-08 17:28:55,959] ERROR   : Internal Server Error: /api/activity
Traceback (most recent call last):
  File "/home/arcturus/Projects/sharewood/venv/lib/python3.7/site-packages/django/core/handlers/exception.py", line 34, in inner
    response = get_response(request)
  File "/home/arcturus/Projects/sharewood/venv/lib/python3.7/site-packages/django/core/handlers/base.py", line 115, in _get_response
    response = self.process_exception_by_middleware(e, request)
  File "/home/arcturus/Projects/sharewood/venv/lib/python3.7/site-packages/django/core/handlers/base.py", line 113, in _get_response
    response = wrapped_callback(request, *callback_args, **callback_kwargs)
  File "/home/arcturus/Projects/sharewood/app/views.py", line 546, in api
    return getattr(app.views_api, data)(request)
  File "/home/arcturus/Projects/sharewood/app/views_api.py", line 25, in activity
    data['last_month'] += 1
KeyError: 'last_month'
[2019-07-08 17:28:59,121] WARNING : Not Found: /favicon.ico
[2019-07-08 17:28:59,141] ERROR   : Internal Server Error: /api/activity
Traceback (most recent call last):
  File "/home/arcturus/Projects/sharewood/venv/lib/python3.7/site-packages/django/core/handlers/exception.py", line 34, in inner
    response = get_response(request)
  File "/home/arcturus/Projects/sharewood/venv/lib/python3.7/site-packages/django/core/handlers/base.py", line 115, in _get_response
    response = self.process_exception_by_middleware(e, request)
  File "/home/arcturus/Projects/sharewood/venv/lib/python3.7/site-packages/django/core/handlers/base.py", line 113, in _get_response
    response = wrapped_callback(request, *callback_args, **callback_kwargs)
  File "/home/arcturus/Projects/sharewood/app/views.py", line 546, in api
    return getattr(app.views_api, data)(request)
  File "/home/arcturus/Projects/sharewood/app/views_api.py", line 25, in activity
    data['last_month'] += 1
KeyError: 'last_month'
[2019-07-08 17:28:59,774] ERROR   : Internal Server Error: /api/activity
Traceback (most recent call last):
  File "/home/arcturus/Projects/sharewood/venv/lib/python3.7/site-packages/django/core/handlers/exception.py", line 34, in inner
    response = get_response(request)
  File "/home/arcturus/Projects/sharewood/venv/lib/python3.7/site-packages/django/core/handlers/base.py", line 115, in _get_response
    response = self.process_exception_by_middleware(e, request)
  File "/home/arcturus/Projects/sharewood/venv/lib/python3.7/site-packages/django/core/handlers/base.py", line 113, in _get_response
    response = wrapped_callback(request, *callback_args, **callback_kwargs)
  File "/home/arcturus/Projects/sharewood/app/views.py", line 546, in api
    return getattr(app.views_api, data)(request)
  File "/home/arcturus/Projects/sharewood/app/views_api.py", line 25, in activity
    data['last_month'] += 1
KeyError: 'last_month'
[2019-07-08 17:29:26,918] ERROR   : Internal Server Error: /api/activity
Traceback (most recent call last):
  File "/home/arcturus/Projects/sharewood/venv/lib/python3.7/site-packages/django/core/handlers/exception.py", line 34, in inner
    response = get_response(request)
  File "/home/arcturus/Projects/sharewood/venv/lib/python3.7/site-packages/django/core/handlers/base.py", line 115, in _get_response
    response = self.process_exception_by_middleware(e, request)
  File "/home/arcturus/Projects/sharewood/venv/lib/python3.7/site-packages/django/core/handlers/base.py", line 113, in _get_response
    response = wrapped_callback(request, *callback_args, **callback_kwargs)
  File "/home/arcturus/Projects/sharewood/app/views.py", line 546, in api
    return getattr(app.views_api, data)(request)
  File "/home/arcturus/Projects/sharewood/app/views_api.py", line 25, in activity
    data['last_month'] += 1
KeyError: 'last_month'
[2019-07-08 17:29:27,196] ERROR   : Internal Server Error: /api/activity
Traceback (most recent call last):
  File "/home/arcturus/Projects/sharewood/venv/lib/python3.7/site-packages/django/core/handlers/exception.py", line 34, in inner
    response = get_response(request)
  File "/home/arcturus/Projects/sharewood/venv/lib/python3.7/site-packages/django/core/handlers/base.py", line 115, in _get_response
    response = self.process_exception_by_middleware(e, request)
  File "/home/arcturus/Projects/sharewood/venv/lib/python3.7/site-packages/django/core/handlers/base.py", line 113, in _get_response
    response = wrapped_callback(request, *callback_args, **callback_kwargs)
  File "/home/arcturus/Projects/sharewood/app/views.py", line 546, in api
    return getattr(app.views_api, data)(request)
  File "/home/arcturus/Projects/sharewood/app/views_api.py", line 25, in activity
    data['last_month'] += 1
KeyError: 'last_month'
[2019-07-08 17:29:28,269] WARNING : Not Found: /favicon.ico
[2019-07-08 17:29:28,288] ERROR   : Internal Server Error: /api/activity
Traceback (most recent call last):
  File "/home/arcturus/Projects/sharewood/venv/lib/python3.7/site-packages/django/core/handlers/exception.py", line 34, in inner
    response = get_response(request)
  File "/home/arcturus/Projects/sharewood/venv/lib/python3.7/site-packages/django/core/handlers/base.py", line 115, in _get_response
    response = self.process_exception_by_middleware(e, request)
  File "/home/arcturus/Projects/sharewood/venv/lib/python3.7/site-packages/django/core/handlers/base.py", line 113, in _get_response
    response = wrapped_callback(request, *callback_args, **callback_kwargs)
  File "/home/arcturus/Projects/sharewood/app/views.py", line 546, in api
    return getattr(app.views_api, data)(request)
  File "/home/arcturus/Projects/sharewood/app/views_api.py", line 25, in activity
    data['last_month'] += 1
KeyError: 'last_month'
[2019-07-08 17:29:44,715] ERROR   : Internal Server Error: /api/activity
Traceback (most recent call last):
  File "/home/arcturus/Projects/sharewood/venv/lib/python3.7/site-packages/django/core/handlers/exception.py", line 34, in inner
    response = get_response(request)
  File "/home/arcturus/Projects/sharewood/venv/lib/python3.7/site-packages/django/core/handlers/base.py", line 115, in _get_response
    response = self.process_exception_by_middleware(e, request)
  File "/home/arcturus/Projects/sharewood/venv/lib/python3.7/site-packages/django/core/handlers/base.py", line 113, in _get_response
    response = wrapped_callback(request, *callback_args, **callback_kwargs)
  File "/home/arcturus/Projects/sharewood/app/views.py", line 546, in api
    return getattr(app.views_api, data)(request)
  File "/home/arcturus/Projects/sharewood/app/views_api.py", line 25, in activity
    data['last_month'] += 1
KeyError: 'last_month'
[2019-07-08 17:29:45,467] ERROR   : Internal Server Error: /api/activity
Traceback (most recent call last):
  File "/home/arcturus/Projects/sharewood/venv/lib/python3.7/site-packages/django/core/handlers/exception.py", line 34, in inner
    response = get_response(request)
  File "/home/arcturus/Projects/sharewood/venv/lib/python3.7/site-packages/django/core/handlers/base.py", line 115, in _get_response
    response = self.process_exception_by_middleware(e, request)
  File "/home/arcturus/Projects/sharewood/venv/lib/python3.7/site-packages/django/core/handlers/base.py", line 113, in _get_response
    response = wrapped_callback(request, *callback_args, **callback_kwargs)
  File "/home/arcturus/Projects/sharewood/app/views.py", line 546, in api
    return getattr(app.views_api, data)(request)
  File "/home/arcturus/Projects/sharewood/app/views_api.py", line 25, in activity
    data['last_month'] += 1
KeyError: 'last_month'
[2019-07-08 17:29:59,680] ERROR   : Internal Server Error: /api/activity
Traceback (most recent call last):
  File "/home/arcturus/Projects/sharewood/venv/lib/python3.7/site-packages/django/core/handlers/exception.py", line 34, in inner
    response = get_response(request)
  File "/home/arcturus/Projects/sharewood/venv/lib/python3.7/site-packages/django/core/handlers/base.py", line 115, in _get_response
    response = self.process_exception_by_middleware(e, request)
  File "/home/arcturus/Projects/sharewood/venv/lib/python3.7/site-packages/django/core/handlers/base.py", line 113, in _get_response
    response = wrapped_callback(request, *callback_args, **callback_kwargs)
  File "/home/arcturus/Projects/sharewood/app/views.py", line 546, in api
    return getattr(app.views_api, data)(request)
  File "/home/arcturus/Projects/sharewood/app/views_api.py", line 25, in activity
    data['last_month'] += 1
KeyError: 'last_month'
[2019-07-08 17:30:13,412] WARNING : Not Found: /favicon.ico
[2019-07-08 17:30:13,436] ERROR   : Internal Server Error: /api/activity
Traceback (most recent call last):
  File "/home/arcturus/Projects/sharewood/venv/lib/python3.7/site-packages/django/core/handlers/exception.py", line 34, in inner
    response = get_response(request)
  File "/home/arcturus/Projects/sharewood/venv/lib/python3.7/site-packages/django/core/handlers/base.py", line 115, in _get_response
    response = self.process_exception_by_middleware(e, request)
  File "/home/arcturus/Projects/sharewood/venv/lib/python3.7/site-packages/django/core/handlers/base.py", line 113, in _get_response
    response = wrapped_callback(request, *callback_args, **callback_kwargs)
  File "/home/arcturus/Projects/sharewood/app/views.py", line 546, in api
    return getattr(app.views_api, data)(request)
  File "/home/arcturus/Projects/sharewood/app/views_api.py", line 25, in activity
    data['last_month'] += 1
KeyError: 'last_month'
[2019-07-08 17:30:14,219] ERROR   : Internal Server Error: /api/activity
Traceback (most recent call last):
  File "/home/arcturus/Projects/sharewood/venv/lib/python3.7/site-packages/django/core/handlers/exception.py", line 34, in inner
    response = get_response(request)
  File "/home/arcturus/Projects/sharewood/venv/lib/python3.7/site-packages/django/core/handlers/base.py", line 115, in _get_response
    response = self.process_exception_by_middleware(e, request)
  File "/home/arcturus/Projects/sharewood/venv/lib/python3.7/site-packages/django/core/handlers/base.py", line 113, in _get_response
    response = wrapped_callback(request, *callback_args, **callback_kwargs)
  File "/home/arcturus/Projects/sharewood/app/views.py", line 546, in api
    return getattr(app.views_api, data)(request)
  File "/home/arcturus/Projects/sharewood/app/views_api.py", line 25, in activity
    data['last_month'] += 1
KeyError: 'last_month'
[2019-07-08 17:30:14,935] WARNING : Not Found: /favicon.ico
[2019-07-08 17:30:14,954] ERROR   : Internal Server Error: /api/activity
Traceback (most recent call last):
  File "/home/arcturus/Projects/sharewood/venv/lib/python3.7/site-packages/django/core/handlers/exception.py", line 34, in inner
    response = get_response(request)
  File "/home/arcturus/Projects/sharewood/venv/lib/python3.7/site-packages/django/core/handlers/base.py", line 115, in _get_response
    response = self.process_exception_by_middleware(e, request)
  File "/home/arcturus/Projects/sharewood/venv/lib/python3.7/site-packages/django/core/handlers/base.py", line 113, in _get_response
    response = wrapped_callback(request, *callback_args, **callback_kwargs)
  File "/home/arcturus/Projects/sharewood/app/views.py", line 546, in api
    return getattr(app.views_api, data)(request)
  File "/home/arcturus/Projects/sharewood/app/views_api.py", line 25, in activity
    data['last_month'] += 1
KeyError: 'last_month'
[2019-07-08 17:30:26,097] ERROR   : Internal Server Error: /api/activity
Traceback (most recent call last):
  File "/home/arcturus/Projects/sharewood/venv/lib/python3.7/site-packages/django/core/handlers/exception.py", line 34, in inner
    response = get_response(request)
  File "/home/arcturus/Projects/sharewood/venv/lib/python3.7/site-packages/django/core/handlers/base.py", line 115, in _get_response
    response = self.process_exception_by_middleware(e, request)
  File "/home/arcturus/Projects/sharewood/venv/lib/python3.7/site-packages/django/core/handlers/base.py", line 113, in _get_response
    response = wrapped_callback(request, *callback_args, **callback_kwargs)
  File "/home/arcturus/Projects/sharewood/app/views.py", line 546, in api
    return getattr(app.views_api, data)(request)
  File "/home/arcturus/Projects/sharewood/app/views_api.py", line 25, in activity
    data['last_month'] += 1
KeyError: 'last_month'
[2019-07-08 17:30:26,811] ERROR   : Internal Server Error: /api/activity
Traceback (most recent call last):
  File "/home/arcturus/Projects/sharewood/venv/lib/python3.7/site-packages/django/core/handlers/exception.py", line 34, in inner
    response = get_response(request)
  File "/home/arcturus/Projects/sharewood/venv/lib/python3.7/site-packages/django/core/handlers/base.py", line 115, in _get_response
    response = self.process_exception_by_middleware(e, request)
  File "/home/arcturus/Projects/sharewood/venv/lib/python3.7/site-packages/django/core/handlers/base.py", line 113, in _get_response
    response = wrapped_callback(request, *callback_args, **callback_kwargs)
  File "/home/arcturus/Projects/sharewood/app/views.py", line 546, in api
    return getattr(app.views_api, data)(request)
  File "/home/arcturus/Projects/sharewood/app/views_api.py", line 25, in activity
    data['last_month'] += 1
KeyError: 'last_month'
[2019-07-08 17:30:27,035] WARNING : Not Found: /favicon.ico
[2019-07-08 17:30:27,222] ERROR   : Internal Server Error: /api/activity
Traceback (most recent call last):
  File "/home/arcturus/Projects/sharewood/venv/lib/python3.7/site-packages/django/core/handlers/exception.py", line 34, in inner
    response = get_response(request)
  File "/home/arcturus/Projects/sharewood/venv/lib/python3.7/site-packages/django/core/handlers/base.py", line 115, in _get_response
    response = self.process_exception_by_middleware(e, request)
  File "/home/arcturus/Projects/sharewood/venv/lib/python3.7/site-packages/django/core/handlers/base.py", line 113, in _get_response
    response = wrapped_callback(request, *callback_args, **callback_kwargs)
  File "/home/arcturus/Projects/sharewood/app/views.py", line 546, in api
    return getattr(app.views_api, data)(request)
  File "/home/arcturus/Projects/sharewood/app/views_api.py", line 25, in activity
    data['last_month'] += 1
KeyError: 'last_month'
[2019-07-08 17:30:28,387] ERROR   : Internal Server Error: /api/activity
Traceback (most recent call last):
  File "/home/arcturus/Projects/sharewood/venv/lib/python3.7/site-packages/django/core/handlers/exception.py", line 34, in inner
    response = get_response(request)
  File "/home/arcturus/Projects/sharewood/venv/lib/python3.7/site-packages/django/core/handlers/base.py", line 115, in _get_response
    response = self.process_exception_by_middleware(e, request)
  File "/home/arcturus/Projects/sharewood/venv/lib/python3.7/site-packages/django/core/handlers/base.py", line 113, in _get_response
    response = wrapped_callback(request, *callback_args, **callback_kwargs)
  File "/home/arcturus/Projects/sharewood/app/views.py", line 546, in api
    return getattr(app.views_api, data)(request)
  File "/home/arcturus/Projects/sharewood/app/views_api.py", line 25, in activity
    data['last_month'] += 1
KeyError: 'last_month'
[2019-07-08 17:30:38,598] ERROR   : Internal Server Error: /api/activity
Traceback (most recent call last):
  File "/home/arcturus/Projects/sharewood/venv/lib/python3.7/site-packages/django/core/handlers/exception.py", line 34, in inner
    response = get_response(request)
  File "/home/arcturus/Projects/sharewood/venv/lib/python3.7/site-packages/django/core/handlers/base.py", line 115, in _get_response
    response = self.process_exception_by_middleware(e, request)
  File "/home/arcturus/Projects/sharewood/venv/lib/python3.7/site-packages/django/core/handlers/base.py", line 113, in _get_response
    response = wrapped_callback(request, *callback_args, **callback_kwargs)
  File "/home/arcturus/Projects/sharewood/app/views.py", line 546, in api
    return getattr(app.views_api, data)(request)
  File "/home/arcturus/Projects/sharewood/app/views_api.py", line 25, in activity
    data['last_month'] += 1
KeyError: 'last_month'
[2019-07-08 17:30:39,301] ERROR   : Internal Server Error: /api/activity
Traceback (most recent call last):
  File "/home/arcturus/Projects/sharewood/venv/lib/python3.7/site-packages/django/core/handlers/exception.py", line 34, in inner
    response = get_response(request)
  File "/home/arcturus/Projects/sharewood/venv/lib/python3.7/site-packages/django/core/handlers/base.py", line 115, in _get_response
    response = self.process_exception_by_middleware(e, request)
  File "/home/arcturus/Projects/sharewood/venv/lib/python3.7/site-packages/django/core/handlers/base.py", line 113, in _get_response
    response = wrapped_callback(request, *callback_args, **callback_kwargs)
  File "/home/arcturus/Projects/sharewood/app/views.py", line 546, in api
    return getattr(app.views_api, data)(request)
  File "/home/arcturus/Projects/sharewood/app/views_api.py", line 25, in activity
    data['last_month'] += 1
KeyError: 'last_month'
[2019-07-08 17:30:49,103] INFO    : /home/arcturus/Projects/sharewood/app/views_api.py changed, reloading.
[2019-07-08 17:31:07,191] WARNING : Not Found: /favicon.ico
[2019-07-08 17:31:09,072] WARNING : Not Found: /favicon.ico
[2019-07-08 17:31:29,180] WARNING : Not Found: /favicon.ico
[2019-07-08 17:31:54,356] WARNING : Not Found: /favicon.ico
[2019-07-08 17:31:54,458] INFO    : /home/arcturus/Projects/sharewood/app/views_api.py changed, reloading.
[2019-07-08 17:31:56,748] WARNING : Not Found: /favicon.ico
[2019-07-08 17:31:56,796] ERROR   : Internal Server Error: /api/activity
Traceback (most recent call last):
  File "/home/arcturus/Projects/sharewood/venv/lib/python3.7/site-packages/django/core/handlers/exception.py", line 34, in inner
    response = get_response(request)
  File "/home/arcturus/Projects/sharewood/venv/lib/python3.7/site-packages/django/core/handlers/base.py", line 115, in _get_response
    response = self.process_exception_by_middleware(e, request)
  File "/home/arcturus/Projects/sharewood/venv/lib/python3.7/site-packages/django/core/handlers/base.py", line 113, in _get_response
    response = wrapped_callback(request, *callback_args, **callback_kwargs)
  File "/home/arcturus/Projects/sharewood/app/views.py", line 546, in api
    return getattr(app.views_api, data)(request)
  File "/home/arcturus/Projects/sharewood/app/views_api.py", line 23, in activity
    data['last_week'] += 1
KeyError: 'last_week'
[2019-07-08 17:31:57,778] ERROR   : Internal Server Error: /api/activity
Traceback (most recent call last):
  File "/home/arcturus/Projects/sharewood/venv/lib/python3.7/site-packages/django/core/handlers/exception.py", line 34, in inner
    response = get_response(request)
  File "/home/arcturus/Projects/sharewood/venv/lib/python3.7/site-packages/django/core/handlers/base.py", line 115, in _get_response
    response = self.process_exception_by_middleware(e, request)
  File "/home/arcturus/Projects/sharewood/venv/lib/python3.7/site-packages/django/core/handlers/base.py", line 113, in _get_response
    response = wrapped_callback(request, *callback_args, **callback_kwargs)
  File "/home/arcturus/Projects/sharewood/app/views.py", line 546, in api
    return getattr(app.views_api, data)(request)
  File "/home/arcturus/Projects/sharewood/app/views_api.py", line 23, in activity
    data['last_week'] += 1
KeyError: 'last_week'
[2019-07-08 17:31:58,528] ERROR   : Internal Server Error: /api/activity
Traceback (most recent call last):
  File "/home/arcturus/Projects/sharewood/venv/lib/python3.7/site-packages/django/core/handlers/exception.py", line 34, in inner
    response = get_response(request)
  File "/home/arcturus/Projects/sharewood/venv/lib/python3.7/site-packages/django/core/handlers/base.py", line 115, in _get_response
    response = self.process_exception_by_middleware(e, request)
  File "/home/arcturus/Projects/sharewood/venv/lib/python3.7/site-packages/django/core/handlers/base.py", line 113, in _get_response
    response = wrapped_callback(request, *callback_args, **callback_kwargs)
  File "/home/arcturus/Projects/sharewood/app/views.py", line 546, in api
    return getattr(app.views_api, data)(request)
  File "/home/arcturus/Projects/sharewood/app/views_api.py", line 23, in activity
    data['last_week'] += 1
KeyError: 'last_week'
[2019-07-08 17:32:40,478] WARNING : Not Found: /api/registrations
[2019-07-08 17:33:54,914] ERROR   : Internal Server Error: /api/activity
Traceback (most recent call last):
  File "/home/arcturus/Projects/sharewood/venv/lib/python3.7/site-packages/django/core/handlers/exception.py", line 34, in inner
    response = get_response(request)
  File "/home/arcturus/Projects/sharewood/venv/lib/python3.7/site-packages/django/core/handlers/base.py", line 115, in _get_response
    response = self.process_exception_by_middleware(e, request)
  File "/home/arcturus/Projects/sharewood/venv/lib/python3.7/site-packages/django/core/handlers/base.py", line 113, in _get_response
    response = wrapped_callback(request, *callback_args, **callback_kwargs)
  File "/home/arcturus/Projects/sharewood/app/views.py", line 546, in api
    return getattr(app.views_api, data)(request)
  File "/home/arcturus/Projects/sharewood/app/views_api.py", line 23, in activity
    data['last_week'] += 1
KeyError: 'last_week'
[2019-07-08 17:33:56,825] ERROR   : Internal Server Error: /api/activity
Traceback (most recent call last):
  File "/home/arcturus/Projects/sharewood/venv/lib/python3.7/site-packages/django/core/handlers/exception.py", line 34, in inner
    response = get_response(request)
  File "/home/arcturus/Projects/sharewood/venv/lib/python3.7/site-packages/django/core/handlers/base.py", line 115, in _get_response
    response = self.process_exception_by_middleware(e, request)
  File "/home/arcturus/Projects/sharewood/venv/lib/python3.7/site-packages/django/core/handlers/base.py", line 113, in _get_response
    response = wrapped_callback(request, *callback_args, **callback_kwargs)
  File "/home/arcturus/Projects/sharewood/app/views.py", line 546, in api
    return getattr(app.views_api, data)(request)
  File "/home/arcturus/Projects/sharewood/app/views_api.py", line 23, in activity
    data['last_week'] += 1
KeyError: 'last_week'
[2019-07-08 17:34:23,572] INFO    : /home/arcturus/Projects/sharewood/app/views_api.py changed, reloading.
